Workbook
Name EmployeeList: OFFSET(_Lists!$C$1,0,0,COUNTIF(_Lists!$C$1:$C$51,"?*"),1)

Sheet Dashboard
A1: CLIENT UTILIZATION & RESOURCE ALLOCATION DASHBOARD
A2: Executive view of deliverables, resource allocation and monthly utilization • filter by Month and Client
A4: FILTERS | C4: Month: | D4: January | F4: Client: | G4: Alpha Appraisal | L4: ◀ Use the dropdowns to update every KPI, chart and table below
A6: FILES RECEIVED | E6: FILES DELIVERED | I6: ON-TIME DELIVERY % | M6: QUALITY %
A7: =SUMIFS(MISData[Files Received],MISData[Month],IF($D$4="All","*",$D$4),MISData[Client Name],IF($G$4="All","*",$G$4)) -> 3 | E7: =SUMIFS(MISData[Files Delivered],MISData[Month],IF($D$4="All","*",$D$4),MISData[Client Name],IF($G$4="All","*",$G$4)) -> 1 | I7: =IFERROR(SUMIFS(MISData[Files Delivered Before Due Date],MISData[Month],IF($D$4="All","*",$D$4),MISData[Client Name],IF($G$4="All","*",$G$4))/SUMIFS(MISData[Files Delivered],MISData[Month],IF($D$4="All","*",$D$4),MISData[Client Name],IF($G$4="All","*",$G$4)),0) -> 1 | M7: =IFERROR(AVERAGEIFS(MISData[Quality %],MISData[Month],IF($D$4="All","*",$D$4),MISData[Client Name],IF($G$4="All","*",$G$4)),0) -> 0.95
A9: PENDING FILES | E9: OVERDUE FILES | I9: TOTAL HOURS (SELECTED CLIENT) | M9: RESOURCES ALLOCATED
A10: =SUMIFS(MISData[Pending Files],MISData[Month],IF($D$4="All","*",$D$4),MISData[Client Name],IF($G$4="All","*",$G$4)) -> 2 | E10: =SUMIFS(MISData[Overdue Files],MISData[Month],IF($D$4="All","*",$D$4),MISData[Client Name],IF($G$4="All","*",$G$4)) -> 1 | I10: =SUM('Utilization Data'!$AB$5:$AB$364) -> 229.5 | M10: =COUNTIF('Utilization Data'!$AB$5:$AB$364,">0") -> 4
A12: EMPLOYEE UTILIZATION | R12: RESOURCE ALLOCATION
R13: # | S13: Resource Name | T13: Hours
C14: Employee: | D14: Rakshitha D | I14: ◀ Uses the Month filter above to scope employee hours | R14: 1 | S14: =IFERROR(INDEX('Utilization Data'!$B$5:$B$364,MATCH(1,'Utilization Data'!$AC$5:$AC$364,0)),"") -> Rakshitha D | T14: =IFERROR(INDEX('Utilization Data'!$AB$5:$AB$364,MATCH(1,'Utilization Data'!$AC$5:$AC$364,0)),"") -> 37.25
R15: 2 | S15: =IFERROR(INDEX('Utilization Data'!$B$5:$B$364,MATCH(2,'Utilization Data'!$AC$5:$AC$364,0)),"") -> Subhicksha K | T15: =IFERROR(INDEX('Utilization Data'!$AB$5:$AB$364,MATCH(2,'Utilization Data'!$AC$5:$AC$364,0)),"") -> 98.5
A16: TOTAL HOURS (SELECTED EMPLOYEE) | E16: CLIENTS SERVED (SELECTED EMPLOYEE) | R16: 3 | S16: =IFERROR(INDEX('Utilization Data'!$B$5:$B$364,MATCH(3,'Utilization Data'!$AC$5:$AC$364,0)),"") -> Reethika S | T16: =IFERROR(INDEX('Utilization Data'!$AB$5:$AB$364,MATCH(3,'Utilization Data'!$AC$5:$AC$364,0)),"") -> 37
A17: =SUM(ChartData!$P$2:$P$21) -> 148 | E17: =COUNTIF(ChartData!$P$2:$P$21,">0") -> 4 | R17: 4 | S17: =IFERROR(INDEX('Utilization Data'!$B$5:$B$364,MATCH(4,'Utilization Data'!$AC$5:$AC$364,0)),"") -> Miruthula Devi | T17: =IFERROR(INDEX('Utilization Data'!$AB$5:$AB$364,MATCH(4,'Utilization Data'!$AC$5:$AC$364,0)),"") -> 56.75
A18: QUALITY % (SELECTED EMPLOYEE) | R18: 5 | S18: =IFERROR(INDEX('Utilization Data'!$B$5:$B$364,MATCH(5,'Utilization Data'!$AC$5:$AC$364,0)),"") | T18: =IFERROR(INDEX('Utilization Data'!$AB$5:$AB$364,MATCH(5,'Utilization Data'!$AC$5:$AC$364,0)),"")
A19: =IF(SUMPRODUCT(ChartData!$P$2:$P$21*ChartData!$T$2:$T$21)=0,"N/A",SUMPRODUCT(ChartData!$P$2:$P$21*ChartData!$S$2:$S$21*ChartData!$T$2:$T$21)/SUMPRODUCT(ChartData!$P$2:$P$21*ChartData!$T$2:$T$21)) -> 0.97827988 | E19: Quality % is tracked by client in the MIS data; shown where available for the clients this employee served. | R19: 6 | S19: =IFERROR(INDEX('Utilization Data'!$B$5:$B$364,MATCH(6,'Utilization Data'!$AC$5:$AC$364,0)),"") | T19: =IFERROR(INDEX('Utilization Data'!$AB$5:$AB$364,MATCH(6,'Utilization Data'!$AC$5:$AC$364,0)),"")
R20: 7 | S20: =IFERROR(INDEX('Utilization Data'!$B$5:$B$364,MATCH(7,'Utilization Data'!$AC$5:$AC$364,0)),"") | T20: =IFERROR(INDEX('Utilization Data'!$AB$5:$AB$364,MATCH(7,'Utilization Data'!$AC$5:$AC$364,0)),"")
A21: # | B21: CLIENT | E21: HOURS | G21: QUALITY % | R21: 8 | S21: =IFERROR(INDEX('Utilization Data'!$B$5:$B$364,MATCH(8,'Utilization Data'!$AC$5:$AC$364,0)),"") | T21: =IFERROR(INDEX('Utilization Data'!$AB$5:$AB$364,MATCH(8,'Utilization Data'!$AC$5:$AC$364,0)),"")
A22: 1 | B22: =IFERROR(INDEX(ChartData!$E$2:$E$21,MATCH(1,ChartData!$Q$2:$Q$21,0)),"") -> FCV | E22: =IFERROR(INDEX(ChartData!$P$2:$P$21,MATCH(1,ChartData!$Q$2:$Q$21,0)),"") -> 12.5 | G22: =IFERROR(INDEX(ChartData!$R$2:$R$21,MATCH(1,ChartData!$Q$2:$Q$21,0)),"") | R22: 9 | S22: =IFERROR(INDEX('Utilization Data'!$B$5:$B$364,MATCH(9,'Utilization Data'!$AC$5:$AC$364,0)),"") | T22: =IFERROR(INDEX('Utilization Data'!$AB$5:$AB$364,MATCH(9,'Utilization Data'!$AC$5:$AC$364,0)),"")
A23: 2 | B23: =IFERROR(INDEX(ChartData!$E$2:$E$21,MATCH(2,ChartData!$Q$2:$Q$21,0)),"") -> Alpha Appraisal | E23: =IFERROR(INDEX(ChartData!$P$2:$P$21,MATCH(2,ChartData!$Q$2:$Q$21,0)),"") -> 37.25 | G23: =IFERROR(INDEX(ChartData!$R$2:$R$21,MATCH(2,ChartData!$Q$2:$Q$21,0)),"") -> 0.95 | R23: 10 | S23: =IFERROR(INDEX('Utilization Data'!$B$5:$B$364,MATCH(10,'Utilization Data'!$AC$5:$AC$364,0)),"") | T23: =IFERROR(INDEX('Utilization Data'!$AB$5:$AB$364,MATCH(10,'Utilization Data'!$AC$5:$AC$364,0)),"")
A24: 3 | B24: =IFERROR(INDEX(ChartData!$E$2:$E$21,MATCH(3,ChartData!$Q$2:$Q$21,0)),"") -> Southwest Property Consultants | E24: =IFERROR(INDEX(ChartData!$P$2:$P$21,MATCH(3,ChartData!$Q$2:$Q$21,0)),"") -> 49.75 | G24: =IFERROR(INDEX(ChartData!$R$2:$R$21,MATCH(3,ChartData!$Q$2:$Q$21,0)),"") | R24: 11 | S24: =IFERROR(INDEX('Utilization Data'!$B$5:$B$364,MATCH(11,'Utilization Data'!$AC$5:$AC$364,0)),"") | T24: =IFERROR(INDEX('Utilization Data'!$AB$5:$AB$364,MATCH(11,'Utilization Data'!$AC$5:$AC$364,0)),"")
A25: 4 | B25: =IFERROR(INDEX(ChartData!$E$2:$E$21,MATCH(4,ChartData!$Q$2:$Q$21,0)),"") -> DP Appraisal | E25: =IFERROR(INDEX(ChartData!$P$2:$P$21,MATCH(4,ChartData!$Q$2:$Q$21,0)),"") -> 48.5 | G25: =IFERROR(INDEX(ChartData!$R$2:$R$21,MATCH(4,ChartData!$Q$2:$Q$21,0)),"") -> 1 | R25: 12 | S25: =IFERROR(INDEX('Utilization Data'!$B$5:$B$364,MATCH(12,'Utilization Data'!$AC$5:$AC$364,0)),"") | T25: =IFERROR(INDEX('Utilization Data'!$AB$5:$AB$364,MATCH(12,'Utilization Data'!$AC$5:$AC$364,0)),"")
A26: 5 | B26: =IFERROR(INDEX(ChartData!$E$2:$E$21,MATCH(5,ChartData!$Q$2:$Q$21,0)),"") | E26: =IFERROR(INDEX(ChartData!$P$2:$P$21,MATCH(5,ChartData!$Q$2:$Q$21,0)),"") | G26: =IFERROR(INDEX(ChartData!$R$2:$R$21,MATCH(5,ChartData!$Q$2:$Q$21,0)),"") | R26: 13 | S26: =IFERROR(INDEX('Utilization Data'!$B$5:$B$364,MATCH(13,'Utilization Data'!$AC$5:$AC$364,0)),"") | T26: =IFERROR(INDEX('Utilization Data'!$AB$5:$AB$364,MATCH(13,'Utilization Data'!$AC$5:$AC$364,0)),"")
A27: 6 | B27: =IFERROR(INDEX(ChartData!$E$2:$E$21,MATCH(6,ChartData!$Q$2:$Q$21,0)),"") | E27: =IFERROR(INDEX(ChartData!$P$2:$P$21,MATCH(6,ChartData!$Q$2:$Q$21,0)),"") | G27: =IFERROR(INDEX(ChartData!$R$2:$R$21,MATCH(6,ChartData!$Q$2:$Q$21,0)),"") | R27: 14 | S27: =IFERROR(INDEX('Utilization Data'!$B$5:$B$364,MATCH(14,'Utilization Data'!$AC$5:$AC$364,0)),"") | T27: =IFERROR(INDEX('Utilization Data'!$AB$5:$AB$364,MATCH(14,'Utilization Data'!$AC$5:$AC$364,0)),"")
A28: 7 | B28: =IFERROR(INDEX(ChartData!$E$2:$E$21,MATCH(7,ChartData!$Q$2:$Q$21,0)),"") | E28: =IFERROR(INDEX(ChartData!$P$2:$P$21,MATCH(7,ChartData!$Q$2:$Q$21,0)),"") | G28: =IFERROR(INDEX(ChartData!$R$2:$R$21,MATCH(7,ChartData!$Q$2:$Q$21,0)),"") | R28: 15 | S28: =IFERROR(INDEX('Utilization Data'!$B$5:$B$364,MATCH(15,'Utilization Data'!$AC$5:$AC$364,0)),"") | T28: =IFERROR(INDEX('Utilization Data'!$AB$5:$AB$364,MATCH(15,'Utilization Data'!$AC$5:$AC$364,0)),"")
A29: 8 | B29: =IFERROR(INDEX(ChartData!$E$2:$E$21,MATCH(8,ChartData!$Q$2:$Q$21,0)),"") | E29: =IFERROR(INDEX(ChartData!$P$2:$P$21,MATCH(8,ChartData!$Q$2:$Q$21,0)),"") | G29: =IFERROR(INDEX(ChartData!$R$2:$R$21,MATCH(8,ChartData!$Q$2:$Q$21,0)),"") | R29: 16 | S29: =IFERROR(INDEX('Utilization Data'!$B$5:$B$364,MATCH(16,'Utilization Data'!$AC$5:$AC$364,0)),"") | T29: =IFERROR(INDEX('Utilization Data'!$AB$5:$AB$364,MATCH(16,'Utilization Data'!$AC$5:$AC$364,0)),"")
A30: 9 | B30: =IFERROR(INDEX(ChartData!$E$2:$E$21,MATCH(9,ChartData!$Q$2:$Q$21,0)),"") | E30: =IFERROR(INDEX(ChartData!$P$2:$P$21,MATCH(9,ChartData!$Q$2:$Q$21,0)),"") | G30: =IFERROR(INDEX(ChartData!$R$2:$R$21,MATCH(9,ChartData!$Q$2:$Q$21,0)),"") | R30: 17 | S30: =IFERROR(INDEX('Utilization Data'!$B$5:$B$364,MATCH(17,'Utilization Data'!$AC$5:$AC$364,0)),"") | T30: =IFERROR(INDEX('Utilization Data'!$AB$5:$AB$364,MATCH(17,'Utilization Data'!$AC$5:$AC$364,0)),"")
A31: 10 | B31: =IFERROR(INDEX(ChartData!$E$2:$E$21,MATCH(10,ChartData!$Q$2:$Q$21,0)),"") | E31: =IFERROR(INDEX(ChartData!$P$2:$P$21,MATCH(10,ChartData!$Q$2:$Q$21,0)),"") | G31: =IFERROR(INDEX(ChartData!$R$2:$R$21,MATCH(10,ChartData!$Q$2:$Q$21,0)),"") | R31: 18 | S31: =IFERROR(INDEX('Utilization Data'!$B$5:$B$364,MATCH(18,'Utilization Data'!$AC$5:$AC$364,0)),"") | T31: =IFERROR(INDEX('Utilization Data'!$AB$5:$AB$364,MATCH(18,'Utilization Data'!$AC$5:$AC$364,0)),"")
A32: 11 | B32: =IFERROR(INDEX(ChartData!$E$2:$E$21,MATCH(11,ChartData!$Q$2:$Q$21,0)),"") | E32: =IFERROR(INDEX(ChartData!$P$2:$P$21,MATCH(11,ChartData!$Q$2:$Q$21,0)),"") | G32: =IFERROR(INDEX(ChartData!$R$2:$R$21,MATCH(11,ChartData!$Q$2:$Q$21,0)),"") | R32: 19 | S32: =IFERROR(INDEX('Utilization Data'!$B$5:$B$364,MATCH(19,'Utilization Data'!$AC$5:$AC$364,0)),"") | T32: =IFERROR(INDEX('Utilization Data'!$AB$5:$AB$364,MATCH(19,'Utilization Data'!$AC$5:$AC$364,0)),"")
A33: 12 | B33: =IFERROR(INDEX(ChartData!$E$2:$E$21,MATCH(12,ChartData!$Q$2:$Q$21,0)),"") | E33: =IFERROR(INDEX(ChartData!$P$2:$P$21,MATCH(12,ChartData!$Q$2:$Q$21,0)),"") | G33: =IFERROR(INDEX(ChartData!$R$2:$R$21,MATCH(12,ChartData!$Q$2:$Q$21,0)),"") | R33: 20 | S33: =IFERROR(INDEX('Utilization Data'!$B$5:$B$364,MATCH(20,'Utilization Data'!$AC$5:$AC$364,0)),"") | T33: =IFERROR(INDEX('Utilization Data'!$AB$5:$AB$364,MATCH(20,'Utilization Data'!$AC$5:$AC$364,0)),"")
A34: 13 | B34: =IFERROR(INDEX(ChartData!$E$2:$E$21,MATCH(13,ChartData!$Q$2:$Q$21,0)),"") | E34: =IFERROR(INDEX(ChartData!$P$2:$P$21,MATCH(13,ChartData!$Q$2:$Q$21,0)),"") | G34: =IFERROR(INDEX(ChartData!$R$2:$R$21,MATCH(13,ChartData!$Q$2:$Q$21,0)),"") | R34: 21 | S34: =IFERROR(INDEX('Utilization Data'!$B$5:$B$364,MATCH(21,'Utilization Data'!$AC$5:$AC$364,0)),"") | T34: =IFERROR(INDEX('Utilization Data'!$AB$5:$AB$364,MATCH(21,'Utilization Data'!$AC$5:$AC$364,0)),"")
A35: 14 | B35: =IFERROR(INDEX(ChartData!$E$2:$E$21,MATCH(14,ChartData!$Q$2:$Q$21,0)),"") | E35: =IFERROR(INDEX(ChartData!$P$2:$P$21,MATCH(14,ChartData!$Q$2:$Q$21,0)),"") | G35: =IFERROR(INDEX(ChartData!$R$2:$R$21,MATCH(14,ChartData!$Q$2:$Q$21,0)),"") | R35: 22 | S35: =IFERROR(INDEX('Utilization Data'!$B$5:$B$364,MATCH(22,'Utilization Data'!$AC$5:$AC$364,0)),"") | T35: =IFERROR(INDEX('Utilization Data'!$AB$5:$AB$364,MATCH(22,'Utilization Data'!$AC$5:$AC$364,0)),"")
A36: 15 | B36: =IFERROR(INDEX(ChartData!$E$2:$E$21,MATCH(15,ChartData!$Q$2:$Q$21,0)),"") | E36: =IFERROR(INDEX(ChartData!$P$2:$P$21,MATCH(15,ChartData!$Q$2:$Q$21,0)),"") | G36: =IFERROR(INDEX(ChartData!$R$2:$R$21,MATCH(15,ChartData!$Q$2:$Q$21,0)),"") | R36: 23 | S36: =IFERROR(INDEX('Utilization Data'!$B$5:$B$364,MATCH(23,'Utilization Data'!$AC$5:$AC$364,0)),"") | T36: =IFERROR(INDEX('Utilization Data'!$AB$5:$AB$364,MATCH(23,'Utilization Data'!$AC$5:$AC$364,0)),"")
A37: 16 | B37: =IFERROR(INDEX(ChartData!$E$2:$E$21,MATCH(16,ChartData!$Q$2:$Q$21,0)),"") | E37: =IFERROR(INDEX(ChartData!$P$2:$P$21,MATCH(16,ChartData!$Q$2:$Q$21,0)),"") | G37: =IFERROR(INDEX(ChartData!$R$2:$R$21,MATCH(16,ChartData!$Q$2:$Q$21,0)),"") | R37: 24 | S37: =IFERROR(INDEX('Utilization Data'!$B$5:$B$364,MATCH(24,'Utilization Data'!$AC$5:$AC$364,0)),"") | T37: =IFERROR(INDEX('Utilization Data'!$AB$5:$AB$364,MATCH(24,'Utilization Data'!$AC$5:$AC$364,0)),"")
A38: 17 | B38: =IFERROR(INDEX(ChartData!$E$2:$E$21,MATCH(17,ChartData!$Q$2:$Q$21,0)),"") | E38: =IFERROR(INDEX(ChartData!$P$2:$P$21,MATCH(17,ChartData!$Q$2:$Q$21,0)),"") | G38: =IFERROR(INDEX(ChartData!$R$2:$R$21,MATCH(17,ChartData!$Q$2:$Q$21,0)),"") | R38: 25 | S38: =IFERROR(INDEX('Utilization Data'!$B$5:$B$364,MATCH(25,'Utilization Data'!$AC$5:$AC$364,0)),"") | T38: =IFERROR(INDEX('Utilization Data'!$AB$5:$AB$364,MATCH(25,'Utilization Data'!$AC$5:$AC$364,0)),"")
A39: 18 | B39: =IFERROR(INDEX(ChartData!$E$2:$E$21,MATCH(18,ChartData!$Q$2:$Q$21,0)),"") | E39: =IFERROR(INDEX(ChartData!$P$2:$P$21,MATCH(18,ChartData!$Q$2:$Q$21,0)),"") | G39: =IFERROR(INDEX(ChartData!$R$2:$R$21,MATCH(18,ChartData!$Q$2:$Q$21,0)),"") | R39: 26 | S39: =IFERROR(INDEX('Utilization Data'!$B$5:$B$364,MATCH(26,'Utilization Data'!$AC$5:$AC$364,0)),"") | T39: =IFERROR(INDEX('Utilization Data'!$AB$5:$AB$364,MATCH(26,'Utilization Data'!$AC$5:$AC$364,0)),"")
A40: 19 | B40: =IFERROR(INDEX(ChartData!$E$2:$E$21,MATCH(19,ChartData!$Q$2:$Q$21,0)),"") | E40: =IFERROR(INDEX(ChartData!$P$2:$P$21,MATCH(19,ChartData!$Q$2:$Q$21,0)),"") | G40: =IFERROR(INDEX(ChartData!$R$2:$R$21,MATCH(19,ChartData!$Q$2:$Q$21,0)),"") | R40: 27 | S40: =IFERROR(INDEX('Utilization Data'!$B$5:$B$364,MATCH(27,'Utilization Data'!$AC$5:$AC$364,0)),"") | T40: =IFERROR(INDEX('Utilization Data'!$AB$5:$AB$364,MATCH(27,'Utilization Data'!$AC$5:$AC$364,0)),"")
A41: 20 | B41: =IFERROR(INDEX(ChartData!$E$2:$E$21,MATCH(20,ChartData!$Q$2:$Q$21,0)),"") | E41: =IFERROR(INDEX(ChartData!$P$2:$P$21,MATCH(20,ChartData!$Q$2:$Q$21,0)),"") | G41: =IFERROR(INDEX(ChartData!$R$2:$R$21,MATCH(20,ChartData!$Q$2:$Q$21,0)),"") | R41: 28 | S41: =IFERROR(INDEX('Utilization Data'!$B$5:$B$364,MATCH(28,'Utilization Data'!$AC$5:$AC$364,0)),"") | T41: =IFERROR(INDEX('Utilization Data'!$AB$5:$AB$364,MATCH(28,'Utilization Data'!$AC$5:$AC$364,0)),"")
A42: TOTAL FOR SELECTED EMPLOYEE | E42: =SUM(E22:E41) -> 148 | G42: =A19 -> 0.97827988 | R42: 29 | S42: =IFERROR(INDEX('Utilization Data'!$B$5:$B$364,MATCH(29,'Utilization Data'!$AC$5:$AC$364,0)),"") | T42: =IFERROR(INDEX('Utilization Data'!$AB$5:$AB$364,MATCH(29,'Utilization Data'!$AC$5:$AC$364,0)),"")
A43: =IF(COUNTIF(E22:E41,">0")=0,"No client hours for this selection","Avg "&TEXT(E42/COUNTIF(E22:E41,">0"),"0.0")&" hrs / client") -> Avg 37.0 hrs / client | R43: 30 | S43: =IFERROR(INDEX('Utilization Data'!$B$5:$B$364,MATCH(30,'Utilization Data'!$AC$5:$AC$364,0)),"") | T43: =IFERROR(INDEX('Utilization Data'!$AB$5:$AB$364,MATCH(30,'Utilization Data'!$AC$5:$AC$364,0)),"")
R44: 31 | S44: =IFERROR(INDEX('Utilization Data'!$B$5:$B$364,MATCH(31,'Utilization Data'!$AC$5:$AC$364,0)),"") | T44: =IFERROR(INDEX('Utilization Data'!$AB$5:$AB$364,MATCH(31,'Utilization Data'!$AC$5:$AC$364,0)),"")
...

Sheet MIS Data
A1: CLIENT-WISE MIS REPORT
A2: Monthly Client Performance Data | Source sheet for the Dashboard
A4: Month | B4: Client Name | C4: Files Received | D4: Files Delivered | E4: Files Delivered Before Due Date | F4: On-Time Delivery % | G4: Quality % | H4: Pending Files | I4: Overdue Files | J4: Resources Allocated | K4: Allocated Hours
A5: January | B5: Alpha Appraisal | C5: 3 | D5: 1 | E5: 1 | F5: =IFERROR(E5/D5,0) -> 1 | G5: 0.95 | H5: =C5-D5 -> 2 | I5: 1 | J5: =SUMPRODUCT((UtilData[Month]=$A5)*(INDEX(UtilData[[FCV]:[Hendry REA]],0,MATCH($B5,'Utilization Data'!$C$4:$V$4,0))>0)) -> 4 | K5: =SUMPRODUCT((UtilData[Month]=$A5)*INDEX(UtilData[[FCV]:[Hendry REA]],0,MATCH($B5,'Utilization Data'!$C$4:$V$4,0))) -> 229.5
A6: January | B6: DP Appraisal | C6: 6 | D6: 6 | E6: 6 | F6: =IFERROR(E6/D6,0) -> 1 | G6: 1 | H6: =C6-D6 -> 0 | I6: 0 | J6: =SUMPRODUCT((UtilData[Month]=$A6)*(INDEX(UtilData[[FCV]:[Hendry REA]],0,MATCH($B6,'Utilization Data'!$C$4:$V$4,0))>0)) -> 5 | K6: =SUMPRODUCT((UtilData[Month]=$A6)*INDEX(UtilData[[FCV]:[Hendry REA]],0,MATCH($B6,'Utilization Data'!$C$4:$V$4,0))) -> 93
A7: February | B7: Alpha Appraisal | C7: 4 | D7: 1 | E7: 1 | F7: =IFERROR(E7/D7,0) -> 1 | G7: 0.95 | H7: =C7-D7 -> 3 | I7: 1 | J7: =SUMPRODUCT((UtilData[Month]=$A7)*(INDEX(UtilData[[FCV]:[Hendry REA]],0,MATCH($B7,'Utilization Data'!$C$4:$V$4,0))>0)) -> 0 | K7: =SUMPRODUCT((UtilData[Month]=$A7)*INDEX(UtilData[[FCV]:[Hendry REA]],0,MATCH($B7,'Utilization Data'!$C$4:$V$4,0))) -> 0
A8: February | B8: DP Appraisal | C8: 2 | D8: 2 | E8: 2 | F8: =IFERROR(E8/D8,0) -> 1 | G8: 0.93 | H8: =C8-D8 -> 0 | I8: 0 | J8: =SUMPRODUCT((UtilData[Month]=$A8)*(INDEX(UtilData[[FCV]:[Hendry REA]],0,MATCH($B8,'Utilization Data'!$C$4:$V$4,0))>0)) -> 0 | K8: =SUMPRODUCT((UtilData[Month]=$A8)*INDEX(UtilData[[FCV]:[Hendry REA]],0,MATCH($B8,'Utilization Data'!$C$4:$V$4,0))) -> 0
A9: March | B9: Alpha Appraisal | C9: 8 | D9: 4 | E9: 3 | F9: =IFERROR(E9/D9,0) -> 0.75 | G9: 0.9 | H9: =C9-D9 -> 4 | I9: 1 | J9: =SUMPRODUCT((UtilData[Month]=$A9)*(INDEX(UtilData[[FCV]:[Hendry REA]],0,MATCH($B9,'Utilization Data'!$C$4:$V$4,0))>0)) -> 0 | K9: =SUMPRODUCT((UtilData[Month]=$A9)*INDEX(UtilData[[FCV]:[Hendry REA]],0,MATCH($B9,'Utilization Data'!$C$4:$V$4,0))) -> 0
A10: March | B10: DP Appraisal | C10: 8 | D10: 8 | E10: 8 | F10: =IFERROR(E10/D10,0) -> 1 | G10: 0.99 | H10: =C10-D10 -> 0 | I10: 0 | J10: =SUMPRODUCT((UtilData[Month]=$A10)*(INDEX(UtilData[[FCV]:[Hendry REA]],0,MATCH($B10,'Utilization Data'!$C$4:$V$4,0))>0)) -> 0 | K10: =SUMPRODUCT((UtilData[Month]=$A10)*INDEX(UtilData[[FCV]:[Hendry REA]],0,MATCH($B10,'Utilization Data'!$C$4:$V$4,0))) -> 0
A11: April | B11: Alpha Appraisal | C11: 2 | D11: 2 | E11: 2 | F11: =IFERROR(E11/D11,0) -> 1 | G11: 0.9 | H11: =C11-D11 -> 0 | I11: 0 | J11: =SUMPRODUCT((UtilData[Month]=$A11)*(INDEX(UtilData[[FCV]:[Hendry REA]],0,MATCH($B11,'Utilization Data'!$C$4:$V$4,0))>0)) -> 0 | K11: =SUMPRODUCT((UtilData[Month]=$A11)*INDEX(UtilData[[FCV]:[Hendry REA]],0,MATCH($B11,'Utilization Data'!$C$4:$V$4,0))) -> 0
A12: April | B12: DP Appraisal | C12: 9 | D12: 9 | E12: 9 | F12: =IFERROR(E12/D12,0) -> 1 | G12: 0.99 | H12: =C12-D12 -> 0 | I12: 0 | J12: =SUMPRODUCT((UtilData[Month]=$A12)*(INDEX(UtilData[[FCV]:[Hendry REA]],0,MATCH($B12,'Utilization Data'!$C$4:$V$4,0))>0)) -> 0 | K12: =SUMPRODUCT((UtilData[Month]=$A12)*INDEX(UtilData[[FCV]:[Hendry REA]],0,MATCH($B12,'Utilization Data'!$C$4:$V$4,0))) -> 0
A13: May | B13: Alpha Appraisal | C13: 4 | D13: 4 | E13: 4 | F13: =IFERROR(E13/D13,0) -> 1 | G13: 0.9 | H13: =C13-D13 -> 0 | I13: 0 | J13: =SUMPRODUCT((UtilData[Month]=$A13)*(INDEX(UtilData[[FCV]:[Hendry REA]],0,MATCH($B13,'Utilization Data'!$C$4:$V$4,0))>0)) -> 0 | K13: =SUMPRODUCT((UtilData[Month]=$A13)*INDEX(UtilData[[FCV]:[Hendry REA]],0,MATCH($B13,'Utilization Data'!$C$4:$V$4,0))) -> 0
A14: May | B14: DP Appraisal | C14: 4 | D14: 3 | E14: 3 | F14: =IFERROR(E14/D14,0) -> 1 | G14: 1 | H14: =C14-D14 -> 1 | I14: 0 | J14: =SUMPRODUCT((UtilData[Month]=$A14)*(INDEX(UtilData[[FCV]:[Hendry REA]],0,MATCH($B14,'Utilization Data'!$C$4:$V$4,0))>0)) -> 0 | K14: =SUMPRODUCT((UtilData[Month]=$A14)*INDEX(UtilData[[FCV]:[Hendry REA]],0,MATCH($B14,'Utilization Data'!$C$4:$V$4,0))) -> 0
A15: June | B15: Alpha Appraisal | C15: 4 | D15: 3 | E15: 1 | F15: =IFERROR(E15/D15,0) -> 0.33333333 | G15: 0.95 | H15: =C15-D15 -> 1 | I15: 0 | J15: =SUMPRODUCT((UtilData[Month]=$A15)*(INDEX(UtilData[[FCV]:[Hendry REA]],0,MATCH($B15,'Utilization Data'!$C$4:$V$4,0))>0)) -> 0 | K15: =SUMPRODUCT((UtilData[Month]=$A15)*INDEX(UtilData[[FCV]:[Hendry REA]],0,MATCH($B15,'Utilization Data'!$C$4:$V$4,0))) -> 0
A16: June | B16: DP Appraisal | C16: 4 | D16: 4 | E16: 4 | F16: =IFERROR(E16/D16,0) -> 1 | G16: 0.85 | H16: =C16-D16 -> 0 | I16: 0 | J16: =SUMPRODUCT((UtilData[Month]=$A16)*(INDEX(UtilData[[FCV]:[Hendry REA]],0,MATCH($B16,'Utilization Data'!$C$4:$V$4,0))>0)) -> 0 | K16: =SUMPRODUCT((UtilData[Month]=$A16)*INDEX(UtilData[[FCV]:[Hendry REA]],0,MATCH($B16,'Utilization Data'!$C$4:$V$4,0))) -> 0
... A18: July | B18: DP Appraisal | C18: 4 | D18: 4 | E18: 4 | F18: =IFERROR(E18/D18,0) -> 1 | G18: 0.969 | H18: =C18-D18 -> 0 | I18: 0 | J18: =SUMPRODUCT((UtilData[Month]=$A18)*(INDEX(UtilData[[FCV]:[Hendry REA]],0,MATCH($B18,'Utilization Data'!$C$4:$V$4,0))>0)) -> 0 | K18: =SUMPRODUCT((UtilData[Month]=$A18)*INDEX(UtilData[[FCV]:[Hendry REA]],0,MATCH($B18,'Utilization Data'!$C$4:$V$4,0))) -> 0

Sheet Utilization Data
A1: CLIENT UTILIZATION TRACKER — RESOURCE HOURS BY CLIENT
A2: Primary input — enter each month's resource hours in the next blank rows (Month, Employee, then hours per client). Dashboard, KPIs and charts update automatically.
A4: Month | B4: Employee | C4: FCV | D4: Alpha Appraisal | E4: EisnerAmper Commercial | F4: GA Group BPP | G4: GA Group Business Valuation | H4: Southwest Property Consultants | I4: Rittenhouse Appraisals | J4: Westrock Appraisal - Commercial | K4: Westrock Appraisal - 71A/B | L4: Westrock Appraisal - Cost Seg | M4: DP Appraisal | N4: Real Point Appraisal | O4: Pointer Appraisal | P4: Leisure Appraisal | Q4: United Appraisal Research | R4: Breland Appraisal | S4: Proven Realty | T4: Voltz Commercial Realty Advisors Inc | U4: Mitchell Valuation | V4: Hendry REA | W4: Sketching | X4: Training | Y4: Other | Z4: Leave | AA4: Total | AB4: SelClientHours | AC4: SelRank | AD4: ClientTotal | AE4: EmpFirst | AF4: EmpRank
A5: January | B5: Sanjay | C5: 6.5 | D5: 0 | E5: 94.25 | F5: 38 | G5: 2.5 | H5: 0 | I5: 0 | J5: 0 | K5: 0 | L5: 0 | M5: 0 | N5: 0 | O5: 0 | P5: 0 | Q5: 0 | R5: 0 | S5: 0 | T5: 0 | U5: 0 | V5: 0 | W5: 0 | X5: 0 | Y5: 0 | Z5: 1 | AA5: =IF($A5="","",SUM($C5:$W5)) -> 141.25 | AB5: =IF($A5="","",IF(OR(Dashboard!$D$4="All",Dashboard!$D$4=$A5),IF(Dashboard!$G$4="All",SUM($C5:$V5),INDEX($C5:$V5,MATCH(Dashboard!$G$4,$C$4:$V$4,0))),0)) -> 0 | AC5: =IF(AND($A5<>"",$AB5>0),SUMPRODUCT(($AB$5:$AB$364>0)*(ROW($AB$5:$AB$364)<=ROW($AB5))),"") | AD5: =IF($A5="",0,SUM($C5:$V5)) -> 141.25 | AE5: =IF($B5="","",IF(COUNTIF($B$5:$B5,$B5)=1,1,0)) -> 1 | AF5: =IF(AE5=1,SUM($AE$5:AE5),"") -> 1
A6: January | B6: Rakshitha D | C6: 12.5 | D6: 37.25 | E6: 0 | F6: 0 | G6: 0 | H6: 49.75 | I6: 0 | J6: 0 | K6: 0 | L6: 0 | M6: 48.5 | N6: 0 | O6: 0 | P6: 0 | Q6: 0 | R6: 0 | S6: 0 | T6: 0 | U6: 0 | V6: 0 | W6: 0 | X6: 0 | Y6: 4 | Z6: 1 | AA6: =IF($A6="","",SUM($C6:$W6)) -> 148 | AB6: =IF($A6="","",IF(OR(Dashboard!$D$4="All",Dashboard!$D$4=$A6),IF(Dashboard!$G$4="All",SUM($C6:$V6),INDEX($C6:$V6,MATCH(Dashboard!$G$4,$C$4:$V$4,0))),0)) -> 37.25 | AC6: =IF(AND($A6<>"",$AB6>0),SUMPRODUCT(($AB$5:$AB$364>0)*(ROW($AB$5:$AB$364)<=ROW($AB6))),"") -> 1 | AD6: =IF($A6="",0,SUM($C6:$V6)) -> 148 | AE6: =IF($B6="","",IF(COUNTIF($B$5:$B6,$B6)=1,1,0)) -> 1 | AF6: =IF(AE6=1,SUM($AE$5:AE6),"") -> 2
A7: January | B7: Vinith | C7: 0 | D7: 0 | E7: 0 | F7: 0 | G7: 0 | H7: 0 | I7: 0 | J7: 157.5 | K7: 0 | L7: 0 | M7: 0 | N7: 0 | O7: 0 | P7: 0 | Q7: 0 | R7: 0 | S7: 0 | T7: 0 | U7: 0 | V7: 0 | W7: 0 | X7: 0 | Y7: 0 | Z7: 0 | AA7: =IF($A7="","",SUM($C7:$W7)) -> 157.5 | AB7: =IF($A7="","",IF(OR(Dashboard!$D$4="All",Dashboard!$D$4=$A7),IF(Dashboard!$G$4="All",SUM($C7:$V7),INDEX($C7:$V7,MATCH(Dashboard!$G$4,$C$4:$V$4,0))),0)) -> 0 | AC7: =IF(AND($A7<>"",$AB7>0),SUMPRODUCT(($AB$5:$AB$364>0)*(ROW($AB$5:$AB$364)<=ROW($AB7))),"") | AD7: =IF($A7="",0,SUM($C7:$V7)) -> 157.5 | AE7: =IF($B7="","",IF(COUNTIF($B$5:$B7,$B7)=1,1,0)) -> 1 | AF7: =IF(AE7=1,SUM($AE$5:AE7),"") -> 3
A8: January | B8: Abinaya K | C8: 0 | D8: 0 | E8: 0 | F8: 0 | G8: 0 | H8: 0 | I8: 0 | J8: 151.5 | K8: 0 | L8: 0 | M8: 0 | N8: 0 | O8: 0 | P8: 0 | Q8: 0 | R8: 0 | S8: 0 | T8: 0 | U8: 0 | V8: 0 | W8: 0 | X8: 0 | Y8: 0 | Z8: 1 | AA8: =IF($A8="","",SUM($C8:$W8)) -> 151.5 | AB8: =IF($A8="","",IF(OR(Dashboard!$D$4="All",Dashboard!$D$4=$A8),IF(Dashboard!$G$4="All",SUM($C8:$V8),INDEX($C8:$V8,MATCH(Dashboard!$G$4,$C$4:$V$4,0))),0)) -> 0 | AC8: =IF(AND($A8<>"",$AB8>0),SUMPRODUCT(($AB$5:$AB$364>0)*(ROW($AB$5:$AB$364)<=ROW($AB8))),"") | AD8: =IF($A8="",0,SUM($C8:$V8)) -> 151.5 | AE8: =IF($B8="","",IF(COUNTIF($B$5:$B8,$B8)=1,1,0)) -> 1 | AF8: =IF(AE8=1,SUM($AE$5:AE8),"") -> 4
A9: January | B9: Subhicksha K | C9: 35 | D9: 98.5 | E9: 0 | F9: 0 | G9: 0 | H9: 0 | I9: 0 | J9: 0 | K9: 0 | L9: 0 | M9: 0 | N9: 0 | O9: 0 | P9: 14 | Q9: 0 | R9: 0 | S9: 0 | T9: 0 | U9: 0 | V9: 0 | W9: 0 | X9: 0 | Y9: 0 | Z9: 1 | AA9: =IF($A9="","",SUM($C9:$W9)) -> 147.5 | AB9: =IF($A9="","",IF(OR(Dashboard!$D$4="All",Dashboard!$D$4=$A9),IF(Dashboard!$G$4="All",SUM($C9:$V9),INDEX($C9:$V9,MATCH(Dashboard!$G$4,$C$4:$V$4,0))),0)) -> 98.5 | AC9: =IF(AND($A9<>"",$AB9>0),SUMPRODUCT(($AB$5:$AB$364>0)*(ROW($AB$5:$AB$364)<=ROW($AB9))),"") -> 2 | AD9: =IF($A9="",0,SUM($C9:$V9)) -> 147.5 | AE9: =IF($B9="","",IF(COUNTIF($B$5:$B9,$B9)=1,1,0)) -> 1 | AF9: =IF(AE9=1,SUM($AE$5:AE9),"") -> 5
A10: January | B10: Shrihari S | C10: 0 | D10: 0 | E10: 0 | F10: 113.75 | G10: 0 | H10: 0 | I10: 0 | J10: 0 | K10: 0 | L10: 0 | M10: 0 | N10: 0 | O10: 0 | P10: 0 | Q10: 0 | R10: 0 | S10: 0 | T10: 0 | U10: 0 | V10: 0 | W10: 0 | X10: 0 | Y10: 0 | Z10: 4.5 | AA10: =IF($A10="","",SUM($C10:$W10)) -> 113.75 | AB10: =IF($A10="","",IF(OR(Dashboard!$D$4="All",Dashboard!$D$4=$A10),IF(Dashboard!$G$4="All",SUM($C10:$V10),INDEX($C10:$V10,MATCH(Dashboard!$G$4,$C$4:$V$4,0))),0)) -> 0 | AC10: =IF(AND($A10<>"",$AB10>0),SUMPRODUCT(($AB$5:$AB$364>0)*(ROW($AB$5:$AB$364)<=ROW($AB10))),"") | AD10: =IF($A10="",0,SUM($C10:$V10)) -> 113.75 | AE10: =IF($B10="","",IF(COUNTIF($B$5:$B10,$B10)=1,1,0)) -> 1 | AF10: =IF(AE10=1,SUM($AE$5:AE10),"") -> 6
A11: January | B11: Madhusree | C11: 0 | D11: 0 | E11: 0 | F11: 4 | G11: 0 | H11: 0 | I11: 0 | J11: 0 | K11: 9 | L11: 0 | M11: 0 | N11: 0 | O11: 0 | P11: 0 | Q11: 0 | R11: 0 | S11: 0 | T11: 0 | U11: 0 | V11: 0 | W11: 0 | X11: 0 | Y11: 7 | Z11: 0 | AA11: =IF($A11="","",SUM($C11:$W11)) -> 13 | AB11: =IF($A11="","",IF(OR(Dashboard!$D$4="All",Dashboard!$D$4=$A11),IF(Dashboard!$G$4="All",SUM($C11:$V11),INDEX($C11:$V11,MATCH(Dashboard!$G$4,$C$4:$V$4,0))),0)) -> 0 | AC11: =IF(AND($A11<>"",$AB11>0),SUMPRODUCT(($AB$5:$AB$364>0)*(ROW($AB$5:$AB$364)<=ROW($AB11))),"") | AD11: =IF($A11="",0,SUM($C11:$V11)) -> 13 | AE11: =IF($B11="","",IF(COUNTIF($B$5:$B11,$B11)=1,1,0)) -> 1 | AF11: =IF(AE11=1,SUM($AE$5:AE11),"") -> 7
A12: January | B12: Ramkumar | C12: 200.25 | D12: 0 | E12: 0 | F12: 0 | G12: 0 | H12: 0 | I12: 0 | J12: 0 | K12: 0 | L12: 0 | M12: 0 | N12: 0 | O12: 0 | P12: 0 | Q12: 0 | R12: 0 | S12: 0 | T12: 0 | U12: 0 | V12: 0 | W12: 0 | X12: 0 | Y12: 0 | Z12: 0 | AA12: =IF($A12="","",SUM($C12:$W12)) -> 200.25 | AB12: =IF($A12="","",IF(OR(Dashboard!$D$4="All",Dashboard!$D$4=$A12),IF(Dashboard!$G$4="All",SUM($C12:$V12),INDEX($C12:$V12,MATCH(Dashboard!$G$4,$C$4:$V$4,0))),0)) -> 0 | AC12: =IF(AND($A12<>"",$AB12>0),SUMPRODUCT(($AB$5:$AB$364>0)*(ROW($AB$5:$AB$364)<=ROW($AB12))),"") | AD12: =IF($A12="",0,SUM($C12:$V12)) -> 200.25 | AE12: =IF($B12="","",IF(COUNTIF($B$5:$B12,$B12)=1,1,0)) -> 1 | AF12: =IF(AE12=1,SUM($AE$5:AE12),"") -> 8
A13: January | B13: Reethika S | C13: 9 | D13: 37 | E13: 0 | F13: 6.75 | G13: 0 | H13: 0 | I13: 0 | J13: 0 | K13: 0 | L13: 0 | M13: 0 | N13: 0 | O13: 0 | P13: 0 | Q13: 0 | R13: 0 | S13: 0 | T13: 0 | U13: 0 | V13: 64 | W13: 0 | X13: 0 | Y13: 37.75 | Z13: 1 | AA13: =IF($A13="","",SUM($C13:$W13)) -> 116.75 | AB13: =IF($A13="","",IF(OR(Dashboard!$D$4="All",Dashboard!$D$4=$A13),IF(Dashboard!$G$4="All",SUM($C13:$V13),INDEX($C13:$V13,MATCH(Dashboard!$G$4,$C$4:$V$4,0))),0)) -> 37 | AC13: =IF(AND($A13<>"",$AB13>0),SUMPRODUCT(($AB$5:$AB$364>0)*(ROW($AB$5:$AB$364)<=ROW($AB13))),"") -> 3 | AD13: =IF($A13="",0,SUM($C13:$V13)) -> 116.75 | AE13: =IF($B13="","",IF(COUNTIF($B$5:$B13,$B13)=1,1,0)) -> 1 | AF13: =IF(AE13=1,SUM($AE$5:AE13),"") -> 9
A14: January | B14: Saran Kumar M | C14: 21 | D14: 0 | E14: 0 | F14: 0 | G14: 0 | H14: 0 | I14: 0 | J14: 0 | K14: 0 | L14: 0 | M14: 0 | N14: 0 | O14: 0 | P14: 0 | Q14: 0 | R14: 0 | S14: 0 | T14: 0 | U14: 0 | V14: 0 | W14: 0 | X14: 0 | Y14: 0 | Z14: 16.5 | AA14: =IF($A14="","",SUM($C14:$W14)) -> 21 | AB14: =IF($A14="","",IF(OR(Dashboard!$D$4="All",Dashboard!$D$4=$A14),IF(Dashboard!$G$4="All",SUM($C14:$V14),INDEX($C14:$V14,MATCH(Dashboard!$G$4,$C$4:$V$4,0))),0)) -> 0 | AC14: =IF(AND($A14<>"",$AB14>0),SUMPRODUCT(($AB$5:$AB$364>0)*(ROW($AB$5:$AB$364)<=ROW($AB14))),"") | AD14: =IF($A14="",0,SUM($C14:$V14)) -> 21 | AE14: =IF($B14="","",IF(COUNTIF($B$5:$B14,$B14)=1,1,0)) -> 1 | AF14: =IF(AE14=1,SUM($AE$5:AE14),"") -> 10
A15: January | B15: Miruthula Devi | C15: 0 | D15: 56.75 | E15: 0 | F15: 41.75 | G15: 0 | H15: 0 | I15: 0 | J15: 0 | K15: 0 | L15: 0 | M15: 19 | N15: 0 | O15: 0 | P15: 0 | Q15: 0 | R15: 0 | S15: 0 | T15: 0 | U15: 0 | V15: 25 | W15: 0 | X15: 0 | Y15: 0 | Z15: 1 | AA15: =IF($A15="","",SUM($C15:$W15)) -> 142.5 | AB15: =IF($A15="","",IF(OR(Dashboard!$D$4="All",Dashboard!$D$4=$A15),IF(Dashboard!$G$4="All",SUM($C15:$V15),INDEX($C15:$V15,MATCH(Dashboard!$G$4,$C$4:$V$4,0))),0)) -> 56.75 | AC15: =IF(AND($A15<>"",$AB15>0),SUMPRODUCT(($AB$5:$AB$364>0)*(ROW($AB$5:$AB$364)<=ROW($AB15))),"") -> 4 | AD15: =IF($A15="",0,SUM($C15:$V15)) -> 142.5 | AE15: =IF($B15="","",IF(COUNTIF($B$5:$B15,$B15)=1,1,0)) -> 1 | AF15: =IF(AE15=1,SUM($AE$5:AE15),"") -> 11
A16: January | B16: Sahdev | C16: 0 | D16: 0 | E16: 0 | F16: 0 | G16: 0 | H16: 0 | I16: 0 | J16: 126 | K16: 0 | L16: 0 | M16: 0 | N16: 0 | O16: 0 | P16: 0 | Q16: 0 | R16: 0 | S16: 0 | T16: 0 | U16: 0 | V16: 0 | W16: 0 | X16: 0 | Y16: 0 | Z16: 3 | AA16: =IF($A16="","",SUM($C16:$W16)) -> 126 | AB16: =IF($A16="","",IF(OR(Dashboard!$D$4="All",Dashboard!$D$4=$A16),IF(Dashboard!$G$4="All",SUM($C16:$V16),INDEX($C16:$V16,MATCH(Dashboard!$G$4,$C$4:$V$4,0))),0)) -> 0 | AC16: =IF(AND($A16<>"",$AB16>0),SUMPRODUCT(($AB$5:$AB$364>0)*(ROW($AB$5:$AB$364)<=ROW($AB16))),"") | AD16: =IF($A16="",0,SUM($C16:$V16)) -> 126 | AE16: =IF($B16="","",IF(COUNTIF($B$5:$B16,$B16)=1,1,0)) -> 1 | AF16: =IF(AE16=1,SUM($AE$5:AE16),"") -> 12
... A34: January | B34: Arun Anbazhagan | C34: 144.5 | D34: 0 | E34: 0 | F34: 0 | G34: 0 | H34: 0 | I34: 0 | J34: 0 | K34: 0 | L34: 0 | M34: 0 | N34: 0 | O34: 0 | P34: 0 | Q34: 0 | R34: 0 | S34: 0 | T34: 0 | U34: 0 | V34: 0 | W34: 0 | X34: 0 | Y34: 0 | Z34: 1 | AA34: =IF($A34="","",SUM($C34:$W34)) -> 144.5 | AB34: =IF($A34="","",IF(OR(Dashboard!$D$4="All",Dashboard!$D$4=$A34),IF(Dashboard!$G$4="All",SUM($C34:$V34),INDEX($C34:$V34,MATCH(Dashboard!$G$4,$C$4:$V$4,0))),0)) -> 0 | AC34: =IF(AND($A34<>"",$AB34>0),SUMPRODUCT(($AB$5:$AB$364>0)*(ROW($AB$5:$AB$364)<=ROW($AB34))),"") | AD34: =IF($A34="",0,SUM($C34:$V34)) -> 144.5 | AE34: =IF($B34="","",IF(COUNTIF($B$5:$B34,$B34)=1,1,0)) -> 1 | AF34: =IF(AE34=1,SUM($AE$5:AE34),"") -> 30
AA35: =IF($A35="","",SUM($C35:$W35)) | AB35: =IF($A35="","",IF(OR(Dashboard!$D$4="All",Dashboard!$D$4=$A35),IF(Dashboard!$G$4="All",SUM($C35:$V35),INDEX($C35:$V35,MATCH(Dashboard!$G$4,$C$4:$V$4,0))),0)) | AC35: =IF(AND($A35<>"",$AB35>0),SUMPRODUCT(($AB$5:$AB$364>0)*(ROW($AB$5:$AB$364)<=ROW($AB35))),"") | AD35: =IF($A35="",0,SUM($C35:$V35)) -> 0 | AE35: =IF($B35="","",IF(COUNTIF($B$5:$B35,$B35)=1,1,0)) | AF35: =IF(AE35=1,SUM($AE$5:AE35),"")
AA36: =IF($A36="","",SUM($C36:$W36)) | AB36: =IF($A36="","",IF(OR(Dashboard!$D$4="All",Dashboard!$D$4=$A36),IF(Dashboard!$G$4="All",SUM($C36:$V36),INDEX($C36:$V36,MATCH(Dashboard!$G$4,$C$4:$V$4,0))),0)) | AC36: =IF(AND($A36<>"",$AB36>0),SUMPRODUCT(($AB$5:$AB$364>0)*(ROW($AB$5:$AB$364)<=ROW($AB36))),"") | AD36: =IF($A36="",0,SUM($C36:$V36)) -> 0 | AE36: =IF($B36="","",IF(COUNTIF($B$5:$B36,$B36)=1,1,0)) | AF36: =IF(AE36=1,SUM($AE$5:AE36),"")
AA37: =IF($A37="","",SUM($C37:$W37)) | AB37: =IF($A37="","",IF(OR(Dashboard!$D$4="All",Dashboard!$D$4=$A37),IF(Dashboard!$G$4="All",SUM($C37:$V37),INDEX($C37:$V37,MATCH(Dashboard!$G$4,$C$4:$V$4,0))),0)) | AC37: =IF(AND($A37<>"",$AB37>0),SUMPRODUCT(($AB$5:$AB$364>0)*(ROW($AB$5:$AB$364)<=ROW($AB37))),"") | AD37: =IF($A37="",0,SUM($C37:$V37)) -> 0 | AE37: =IF($B37="","",IF(COUNTIF($B$5:$B37,$B37)=1,1,0)) | AF37: =IF(AE37=1,SUM($AE$5:AE37),"")
AA38: =IF($A38="","",SUM($C38:$W38)) | AB38: =IF($A38="","",IF(OR(Dashboard!$D$4="All",Dashboard!$D$4=$A38),IF(Dashboard!$G$4="All",SUM($C38:$V38),INDEX($C38:$V38,MATCH(Dashboard!$G$4,$C$4:$V$4,0))),0)) | AC38: =IF(AND($A38<>"",$AB38>0),SUMPRODUCT(($AB$5:$AB$364>0)*(ROW($AB$5:$AB$364)<=ROW($AB38))),"") | AD38: =IF($A38="",0,SUM($C38:$V38)) -> 0 | AE38: =IF($B38="","",IF(COUNTIF($B$5:$B38,$B38)=1,1,0)) | AF38: =IF(AE38=1,SUM($AE$5:AE38),"")
AA39: =IF($A39="","",SUM($C39:$W39)) | AB39: =IF($A39="","",IF(OR(Dashboard!$D$4="All",Dashboard!$D$4=$A39),IF(Dashboard!$G$4="All",SUM($C39:$V39),INDEX($C39:$V39,MATCH(Dashboard!$G$4,$C$4:$V$4,0))),0)) | AC39: =IF(AND($A39<>"",$AB39>0),SUMPRODUCT(($AB$5:$AB$364>0)*(ROW($AB$5:$AB$364)<=ROW($AB39))),"") | AD39: =IF($A39="",0,SUM($C39:$V39)) -> 0 | AE39: =IF($B39="","",IF(COUNTIF($B$5:$B39,$B39)=1,1,0)) | AF39: =IF(AE39=1,SUM($AE$5:AE39),"")
AA40: =IF($A40="","",SUM($C40:$W40)) | AB40: =IF($A40="","",IF(OR(Dashboard!$D$4="All",Dashboard!$D$4=$A40),IF(Dashboard!$G$4="All",SUM($C40:$V40),INDEX($C40:$V40,MATCH(Dashboard!$G$4,$C$4:$V$4,0))),0)) | AC40: =IF(AND($A40<>"",$AB40>0),SUMPRODUCT(($AB$5:$AB$364>0)*(ROW($AB$5:$AB$364)<=ROW($AB40))),"") | AD40: =IF($A40="",0,SUM($C40:$V40)) -> 0 | AE40: =IF($B40="","",IF(COUNTIF($B$5:$B40,$B40)=1,1,0)) | AF40: =IF(AE40=1,SUM($AE$5:AE40),"")
AA41: =IF($A41="","",SUM($C41:$W41)) | AB41: =IF($A41="","",IF(OR(Dashboard!$D$4="All",Dashboard!$D$4=$A41),IF(Dashboard!$G$4="All",SUM($C41:$V41),INDEX($C41:$V41,MATCH(Dashboard!$G$4,$C$4:$V$4,0))),0)) | AC41: =IF(AND($A41<>"",$AB41>0),SUMPRODUCT(($AB$5:$AB$364>0)*(ROW($AB$5:$AB$364)<=ROW($AB41))),"") | AD41: =IF($A41="",0,SUM($C41:$V41)) -> 0 | AE41: =IF($B41="","",IF(COUNTIF($B$5:$B41,$B41)=1,1,0)) | AF41: =IF(AE41=1,SUM($AE$5:AE41),"")
AA42: =IF($A42="","",SUM($C42:$W42)) | AB42: =IF($A42="","",IF(OR(Dashboard!$D$4="All",Dashboard!$D$4=$A42),IF(Dashboard!$G$4="All",SUM($C42:$V42),INDEX($C42:$V42,MATCH(Dashboard!$G$4,$C$4:$V$4,0))),0)) | AC42: =IF(AND($A42<>"",$AB42>0),SUMPRODUCT(($AB$5:$AB$364>0)*(ROW($AB$5:$AB$364)<=ROW($AB42))),"") | AD42: =IF($A42="",0,SUM($C42:$V42)) -> 0 | AE42: =IF($B42="","",IF(COUNTIF($B$5:$B42,$B42)=1,1,0)) | AF42: =IF(AE42=1,SUM($AE$5:AE42),"")
AA43: =IF($A43="","",SUM($C43:$W43)) | AB43: =IF($A43="","",IF(OR(Dashboard!$D$4="All",Dashboard!$D$4=$A43),IF(Dashboard!$G$4="All",SUM($C43:$V43),INDEX($C43:$V43,MATCH(Dashboard!$G$4,$C$4:$V$4,0))),0)) | AC43: =IF(AND($A43<>"",$AB43>0),SUMPRODUCT(($AB$5:$AB$364>0)*(ROW($AB$5:$AB$364)<=ROW($AB43))),"") | AD43: =IF($A43="",0,SUM($C43:$V43)) -> 0 | AE43: =IF($B43="","",IF(COUNTIF($B$5:$B43,$B43)=1,1,0)) | AF43: =IF(AE43=1,SUM($AE$5:AE43),"")
AA44: =IF($A44="","",SUM($C44:$W44)) | AB44: =IF($A44="","",IF(OR(Dashboard!$D$4="All",Dashboard!$D$4=$A44),IF(Dashboard!$G$4="All",SUM($C44:$V44),INDEX($C44:$V44,MATCH(Dashboard!$G$4,$C$4:$V$4,0))),0)) | AC44: =IF(AND($A44<>"",$AB44>0),SUMPRODUCT(($AB$5:$AB$364>0)*(ROW($AB$5:$AB$364)<=ROW($AB44))),"") | AD44: =IF($A44="",0,SUM($C44:$V44)) -> 0 | AE44: =IF($B44="","",IF(COUNTIF($B$5:$B44,$B44)=1,1,0)) | AF44: =IF(AE44=1,SUM($AE$5:AE44),"")
AA45: =IF($A45="","",SUM($C45:$W45)) | AB45: =IF($A45="","",IF(OR(Dashboard!$D$4="All",Dashboard!$D$4=$A45),IF(Dashboard!$G$4="All",SUM($C45:$V45),INDEX($C45:$V45,MATCH(Dashboard!$G$4,$C$4:$V$4,0))),0)) | AC45: =IF(AND($A45<>"",$AB45>0),SUMPRODUCT(($AB$5:$AB$364>0)*(ROW($AB$5:$AB$364)<=ROW($AB45))),"") | AD45: =IF($A45="",0,SUM($C45:$V45)) -> 0 | AE45: =IF($B45="","",IF(COUNTIF($B$5:$B45,$B45)=1,1,0)) | AF45: =IF(AE45=1,SUM($AE$5:AE45),"")
AA46: =IF($A46="","",SUM($C46:$W46)) | AB46: =IF($A46="","",IF(OR(Dashboard!$D$4="All",Dashboard!$D$4=$A46),IF(Dashboard!$G$4="All",SUM($C46:$V46),INDEX($C46:$V46,MATCH(Dashboard!$G$4,$C$4:$V$4,0))),0)) | AC46: =IF(AND($A46<>"",$AB46>0),SUMPRODUCT(($AB$5:$AB$364>0)*(ROW($AB$5:$AB$364)<=ROW($AB46))),"") | AD46: =IF($A46="",0,SUM($C46:$V46)) -> 0 | AE46: =IF($B46="","",IF(COUNTIF($B$5:$B46,$B46)=1,1,0)) | AF46: =IF(AE46=1,SUM($AE$5:AE46),"")
... AA364: =IF($A364="","",SUM($C364:$W364)) | AB364: =IF($A364="","",IF(OR(Dashboard!$D$4="All",Dashboard!$D$4=$A364),IF(Dashboard!$G$4="All",SUM($C364:$V364),INDEX($C364:$V364,MATCH(Dashboard!$G$4,$C$4:$V$4,0))),0)) | AC364: =IF(AND($A364<>"",$AB364>0),SUMPRODUCT(($AB$5:$AB$364>0)*(ROW($AB$5:$AB$364)<=ROW($AB364))),"") | AD364: =IF($A364="",0,SUM($C364:$V364)) -> 0 | AE364: =IF($B364="","",IF(COUNTIF($B$5:$B364,$B364)=1,1,0)) | AF364: =IF(AE364=1,SUM($AE$5:AE364),"")

Sheet ChartData
A1: Month | B1: Files Received | C1: Files Delivered | E1: Client | F1: Hours | H1: Month | I1: Hours | K1: Month | L1: Total Client Hours | N1: All | P1: Employee Hours | Q1: EmpRank | R1: Quality % | S1: QualityNum | T1: HasQuality
A2: January | B2: =SUMIFS(MISData[Files Received],MISData[Month],$A2,MISData[Client Name],IF(Dashboard!$G$4="All","*",Dashboard!$G$4)) -> 3 | C2: =SUMIFS(MISData[Files Delivered],MISData[Month],$A2,MISData[Client Name],IF(Dashboard!$G$4="All","*",Dashboard!$G$4)) -> 1 | E2: FCV | F2: =SUMPRODUCT((((('Utilization Data'!$A$5:$A$364=Dashboard!$D$4)+(Dashboard!$D$4="All"))>0))*1,INDEX('Utilization Data'!$C$5:$V$364,0,MATCH($E2,'Utilization Data'!$C$4:$V$4,0))) -> 807 | H2: January | I2: =IF(Dashboard!$G$4="All",SUMPRODUCT(('Utilization Data'!$A$5:$A$364=$H2)*'Utilization Data'!$AD$5:$AD$364),SUMPRODUCT(('Utilization Data'!$A$5:$A$364=$H2)*INDEX('Utilization Data'!$C$5:$V$364,0,MATCH(Dashboard!$G$4,'Utilization Data'!$C$4:$V$4,0)))) -> 229.5 | K2: January | L2: =SUMPRODUCT(('Utilization Data'!$A$5:$A$364=$K2)*'Utilization Data'!$AD$5:$AD$364) -> 3397.25 | N2: FCV | P2: =SUMPRODUCT(((('Utilization Data'!$A$5:$A$364=Dashboard!$D$4)+(Dashboard!$D$4="All"))>0)*(((('Utilization Data'!$B$5:$B$364=Dashboard!$D$14)+(Dashboard!$D$14="All"))>0)),INDEX('Utilization Data'!$C$5:$V$364,0,MATCH($E2,'Utilization Data'!$C$4:$V$4,0))) -> 12.5 | Q2: =IF(P2>0,SUMPRODUCT(($P$2:$P$21>0)*(ROW($P$2:$P$21)<=ROW(P2))),"") -> 1 | R2: =IFERROR(AVERAGEIFS(MISData[Quality %],MISData[Month],IF(Dashboard!$D$4="All","*",Dashboard!$D$4),MISData[Client Name],$E2),"") | S2: =IF(R2="",0,R2) -> 0 | T2: =IF(R2="",0,1) -> 0
A3: February | B3: =SUMIFS(MISData[Files Received],MISData[Month],$A3,MISData[Client Name],IF(Dashboard!$G$4="All","*",Dashboard!$G$4)) -> 4 | C3: =SUMIFS(MISData[Files Delivered],MISData[Month],$A3,MISData[Client Name],IF(Dashboard!$G$4="All","*",Dashboard!$G$4)) -> 1 | E3: Alpha Appraisal | F3: =SUMPRODUCT((((('Utilization Data'!$A$5:$A$364=Dashboard!$D$4)+(Dashboard!$D$4="All"))>0))*1,INDEX('Utilization Data'!$C$5:$V$364,0,MATCH($E3,'Utilization Data'!$C$4:$V$4,0))) -> 229.5 | H3: February | I3: =IF(Dashboard!$G$4="All",SUMPRODUCT(('Utilization Data'!$A$5:$A$364=$H3)*'Utilization Data'!$AD$5:$AD$364),SUMPRODUCT(('Utilization Data'!$A$5:$A$364=$H3)*INDEX('Utilization Data'!$C$5:$V$364,0,MATCH(Dashboard!$G$4,'Utilization Data'!$C$4:$V$4,0)))) -> 0 | K3: February | L3: =SUMPRODUCT(('Utilization Data'!$A$5:$A$364=$K3)*'Utilization Data'!$AD$5:$AD$364) -> 0 | N3: Alpha Appraisal | P3: =SUMPRODUCT(((('Utilization Data'!$A$5:$A$364=Dashboard!$D$4)+(Dashboard!$D$4="All"))>0)*(((('Utilization Data'!$B$5:$B$364=Dashboard!$D$14)+(Dashboard!$D$14="All"))>0)),INDEX('Utilization Data'!$C$5:$V$364,0,MATCH($E3,'Utilization Data'!$C$4:$V$4,0))) -> 37.25 | Q3: =IF(P3>0,SUMPRODUCT(($P$2:$P$21>0)*(ROW($P$2:$P$21)<=ROW(P3))),"") -> 2 | R3: =IFERROR(AVERAGEIFS(MISData[Quality %],MISData[Month],IF(Dashboard!$D$4="All","*",Dashboard!$D$4),MISData[Client Name],$E3),"") -> 0.95 | S3: =IF(R3="",0,R3) -> 0.95 | T3: =IF(R3="",0,1) -> 1
A4: March | B4: =SUMIFS(MISData[Files Received],MISData[Month],$A4,MISData[Client Name],IF(Dashboard!$G$4="All","*",Dashboard!$G$4)) -> 8 | C4: =SUMIFS(MISData[Files Delivered],MISData[Month],$A4,MISData[Client Name],IF(Dashboard!$G$4="All","*",Dashboard!$G$4)) -> 4 | E4: EisnerAmper Commercial | F4: =SUMPRODUCT((((('Utilization Data'!$A$5:$A$364=Dashboard!$D$4)+(Dashboard!$D$4="All"))>0))*1,INDEX('Utilization Data'!$C$5:$V$364,0,MATCH($E4,'Utilization Data'!$C$4:$V$4,0))) -> 368.25 | H4: March | I4: =IF(Dashboard!$G$4="All",SUMPRODUCT(('Utilization Data'!$A$5:$A$364=$H4)*'Utilization Data'!$AD$5:$AD$364),SUMPRODUCT(('Utilization Data'!$A$5:$A$364=$H4)*INDEX('Utilization Data'!$C$5:$V$364,0,MATCH(Dashboard!$G$4,'Utilization Data'!$C$4:$V$4,0)))) -> 0 | K4: March | L4: =SUMPRODUCT(('Utilization Data'!$A$5:$A$364=$K4)*'Utilization Data'!$AD$5:$AD$364) -> 0 | N4: EisnerAmper Commercial | P4: =SUMPRODUCT(((('Utilization Data'!$A$5:$A$364=Dashboard!$D$4)+(Dashboard!$D$4="All"))>0)*(((('Utilization Data'!$B$5:$B$364=Dashboard!$D$14)+(Dashboard!$D$14="All"))>0)),INDEX('Utilization Data'!$C$5:$V$364,0,MATCH($E4,'Utilization Data'!$C$4:$V$4,0))) -> 0 | Q4: =IF(P4>0,SUMPRODUCT(($P$2:$P$21>0)*(ROW($P$2:$P$21)<=ROW(P4))),"") | R4: =IFERROR(AVERAGEIFS(MISData[Quality %],MISData[Month],IF(Dashboard!$D$4="All","*",Dashboard!$D$4),MISData[Client Name],$E4),"") | S4: =IF(R4="",0,R4) -> 0 | T4: =IF(R4="",0,1) -> 0
A5: April | B5: =SUMIFS(MISData[Files Received],MISData[Month],$A5,MISData[Client Name],IF(Dashboard!$G$4="All","*",Dashboard!$G$4)) -> 2 | C5: =SUMIFS(MISData[Files Delivered],MISData[Month],$A5,MISData[Client Name],IF(Dashboard!$G$4="All","*",Dashboard!$G$4)) -> 2 | E5: GA Group BPP | F5: =SUMPRODUCT((((('Utilization Data'!$A$5:$A$364=Dashboard!$D$4)+(Dashboard!$D$4="All"))>0))*1,INDEX('Utilization Data'!$C$5:$V$364,0,MATCH($E5,'Utilization Data'!$C$4:$V$4,0))) -> 825.25 | H5: April | I5: =IF(Dashboard!$G$4="All",SUMPRODUCT(('Utilization Data'!$A$5:$A$364=$H5)*'Utilization Data'!$AD$5:$AD$364),SUMPRODUCT(('Utilization Data'!$A$5:$A$364=$H5)*INDEX('Utilization Data'!$C$5:$V$364,0,MATCH(Dashboard!$G$4,'Utilization Data'!$C$4:$V$4,0)))) -> 0 | K5: April | L5: =SUMPRODUCT(('Utilization Data'!$A$5:$A$364=$K5)*'Utilization Data'!$AD$5:$AD$364) -> 0 | N5: GA Group BPP | P5: =SUMPRODUCT(((('Utilization Data'!$A$5:$A$364=Dashboard!$D$4)+(Dashboard!$D$4="All"))>0)*(((('Utilization Data'!$B$5:$B$364=Dashboard!$D$14)+(Dashboard!$D$14="All"))>0)),INDEX('Utilization Data'!$C$5:$V$364,0,MATCH($E5,'Utilization Data'!$C$4:$V$4,0))) -> 0 | Q5: =IF(P5>0,SUMPRODUCT(($P$2:$P$21>0)*(ROW($P$2:$P$21)<=ROW(P5))),"") | R5: =IFERROR(AVERAGEIFS(MISData[Quality %],MISData[Month],IF(Dashboard!$D$4="All","*",Dashboard!$D$4),MISData[Client Name],$E5),"") | S5: =IF(R5="",0,R5) -> 0 | T5: =IF(R5="",0,1) -> 0
A6: May | B6: =SUMIFS(MISData[Files Received],MISData[Month],$A6,MISData[Client Name],IF(Dashboard!$G$4="All","*",Dashboard!$G$4)) -> 4 | C6: =SUMIFS(MISData[Files Delivered],MISData[Month],$A6,MISData[Client Name],IF(Dashboard!$G$4="All","*",Dashboard!$G$4)) -> 4 | E6: GA Group Business Valuation | F6: =SUMPRODUCT((((('Utilization Data'!$A$5:$A$364=Dashboard!$D$4)+(Dashboard!$D$4="All"))>0))*1,INDEX('Utilization Data'!$C$5:$V$364,0,MATCH($E6,'Utilization Data'!$C$4:$V$4,0))) -> 93.5 | H6: May | I6: =IF(Dashboard!$G$4="All",SUMPRODUCT(('Utilization Data'!$A$5:$A$364=$H6)*'Utilization Data'!$AD$5:$AD$364),SUMPRODUCT(('Utilization Data'!$A$5:$A$364=$H6)*INDEX('Utilization Data'!$C$5:$V$364,0,MATCH(Dashboard!$G$4,'Utilization Data'!$C$4:$V$4,0)))) -> 0 | K6: May | L6: =SUMPRODUCT(('Utilization Data'!$A$5:$A$364=$K6)*'Utilization Data'!$AD$5:$AD$364) -> 0 | N6: GA Group Business Valuation | P6: =SUMPRODUCT(((('Utilization Data'!$A$5:$A$364=Dashboard!$D$4)+(Dashboard!$D$4="All"))>0)*(((('Utilization Data'!$B$5:$B$364=Dashboard!$D$14)+(Dashboard!$D$14="All"))>0)),INDEX('Utilization Data'!$C$5:$V$364,0,MATCH($E6,'Utilization Data'!$C$4:$V$4,0))) -> 0 | Q6: =IF(P6>0,SUMPRODUCT(($P$2:$P$21>0)*(ROW($P$2:$P$21)<=ROW(P6))),"") | R6: =IFERROR(AVERAGEIFS(MISData[Quality %],MISData[Month],IF(Dashboard!$D$4="All","*",Dashboard!$D$4),MISData[Client Name],$E6),"") | S6: =IF(R6="",0,R6) -> 0 | T6: =IF(R6="",0,1) -> 0
A7: June | B7: =SUMIFS(MISData[Files Received],MISData[Month],$A7,MISData[Client Name],IF(Dashboard!$G$4="All","*",Dashboard!$G$4)) -> 4 | C7: =SUMIFS(MISData[Files Delivered],MISData[Month],$A7,MISData[Client Name],IF(Dashboard!$G$4="All","*",Dashboard!$G$4)) -> 3 | E7: Southwest Property Consultants | F7: =SUMPRODUCT((((('Utilization Data'!$A$5:$A$364=Dashboard!$D$4)+(Dashboard!$D$4="All"))>0))*1,INDEX('Utilization Data'!$C$5:$V$364,0,MATCH($E7,'Utilization Data'!$C$4:$V$4,0))) -> 169.75 | H7: June | I7: =IF(Dashboard!$G$4="All",SUMPRODUCT(('Utilization Data'!$A$5:$A$364=$H7)*'Utilization Data'!$AD$5:$AD$364),SUMPRODUCT(('Utilization Data'!$A$5:$A$364=$H7)*INDEX('Utilization Data'!$C$5:$V$364,0,MATCH(Dashboard!$G$4,'Utilization Data'!$C$4:$V$4,0)))) -> 0 | K7: June | L7: =SUMPRODUCT(('Utilization Data'!$A$5:$A$364=$K7)*'Utilization Data'!$AD$5:$AD$364) -> 0 | N7: Southwest Property Consultants | P7: =SUMPRODUCT(((('Utilization Data'!$A$5:$A$364=Dashboard!$D$4)+(Dashboard!$D$4="All"))>0)*(((('Utilization Data'!$B$5:$B$364=Dashboard!$D$14)+(Dashboard!$D$14="All"))>0)),INDEX('Utilization Data'!$C$5:$V$364,0,MATCH($E7,'Utilization Data'!$C$4:$V$4,0))) -> 49.75 | Q7: =IF(P7>0,SUMPRODUCT(($P$2:$P$21>0)*(ROW($P$2:$P$21)<=ROW(P7))),"") -> 3 | R7: =IFERROR(AVERAGEIFS(MISData[Quality %],MISData[Month],IF(Dashboard!$D$4="All","*",Dashboard!$D$4),MISData[Client Name],$E7),"") | S7: =IF(R7="",0,R7) -> 0 | T7: =IF(R7="",0,1) -> 0
A8: July | B8: =SUMIFS(MISData[Files Received],MISData[Month],$A8,MISData[Client Name],IF(Dashboard!$G$4="All","*",Dashboard!$G$4)) -> 3 | C8: =SUMIFS(MISData[Files Delivered],MISData[Month],$A8,MISData[Client Name],IF(Dashboard!$G$4="All","*",Dashboard!$G$4)) -> 3 | E8: Rittenhouse Appraisals | F8: =SUMPRODUCT((((('Utilization Data'!$A$5:$A$364=Dashboard!$D$4)+(Dashboard!$D$4="All"))>0))*1,INDEX('Utilization Data'!$C$5:$V$364,0,MATCH($E8,'Utilization Data'!$C$4:$V$4,0))) -> 0 | H8: July | I8: =IF(Dashboard!$G$4="All",SUMPRODUCT(('Utilization Data'!$A$5:$A$364=$H8)*'Utilization Data'!$AD$5:$AD$364),SUMPRODUCT(('Utilization Data'!$A$5:$A$364=$H8)*INDEX('Utilization Data'!$C$5:$V$364,0,MATCH(Dashboard!$G$4,'Utilization Data'!$C$4:$V$4,0)))) -> 0 | K8: July | L8: =SUMPRODUCT(('Utilization Data'!$A$5:$A$364=$K8)*'Utilization Data'!$AD$5:$AD$364) -> 0 | N8: Rittenhouse Appraisals | P8: =SUMPRODUCT(((('Utilization Data'!$A$5:$A$364=Dashboard!$D$4)+(Dashboard!$D$4="All"))>0)*(((('Utilization Data'!$B$5:$B$364=Dashboard!$D$14)+(Dashboard!$D$14="All"))>0)),INDEX('Utilization Data'!$C$5:$V$364,0,MATCH($E8,'Utilization Data'!$C$4:$V$4,0))) -> 0 | Q8: =IF(P8>0,SUMPRODUCT(($P$2:$P$21>0)*(ROW($P$2:$P$21)<=ROW(P8))),"") | R8: =IFERROR(AVERAGEIFS(MISData[Quality %],MISData[Month],IF(Dashboard!$D$4="All","*",Dashboard!$D$4),MISData[Client Name],$E8),"") | S8: =IF(R8="",0,R8) -> 0 | T8: =IF(R8="",0,1) -> 0
A9: August | B9: =SUMIFS(MISData[Files Received],MISData[Month],$A9,MISData[Client Name],IF(Dashboard!$G$4="All","*",Dashboard!$G$4)) -> 0 | C9: =SUMIFS(MISData[Files Delivered],MISData[Month],$A9,MISData[Client Name],IF(Dashboard!$G$4="All","*",Dashboard!$G$4)) -> 0 | E9: Westrock Appraisal - Commercial | F9: =SUMPRODUCT((((('Utilization Data'!$A$5:$A$364=Dashboard!$D$4)+(Dashboard!$D$4="All"))>0))*1,INDEX('Utilization Data'!$C$5:$V$364,0,MATCH($E9,'Utilization Data'!$C$4:$V$4,0))) -> 502 | H9: August | I9: =IF(Dashboard!$G$4="All",SUMPRODUCT(('Utilization Data'!$A$5:$A$364=$H9)*'Utilization Data'!$AD$5:$AD$364),SUMPRODUCT(('Utilization Data'!$A$5:$A$364=$H9)*INDEX('Utilization Data'!$C$5:$V$364,0,MATCH(Dashboard!$G$4,'Utilization Data'!$C$4:$V$4,0)))) -> 0 | K9: August | L9: =SUMPRODUCT(('Utilization Data'!$A$5:$A$364=$K9)*'Utilization Data'!$AD$5:$AD$364) -> 0 | N9: Westrock Appraisal - Commercial | P9: =SUMPRODUCT(((('Utilization Data'!$A$5:$A$364=Dashboard!$D$4)+(Dashboard!$D$4="All"))>0)*(((('Utilization Data'!$B$5:$B$364=Dashboard!$D$14)+(Dashboard!$D$14="All"))>0)),INDEX('Utilization Data'!$C$5:$V$364,0,MATCH($E9,'Utilization Data'!$C$4:$V$4,0))) -> 0 | Q9: =IF(P9>0,SUMPRODUCT(($P$2:$P$21>0)*(ROW($P$2:$P$21)<=ROW(P9))),"") | R9: =IFERROR(AVERAGEIFS(MISData[Quality %],MISData[Month],IF(Dashboard!$D$4="All","*",Dashboard!$D$4),MISData[Client Name],$E9),"") | S9: =IF(R9="",0,R9) -> 0 | T9: =IF(R9="",0,1) -> 0
A10: September | B10: =SUMIFS(MISData[Files Received],MISData[Month],$A10,MISData[Client Name],IF(Dashboard!$G$4="All","*",Dashboard!$G$4)) -> 0 | C10: =SUMIFS(MISData[Files Delivered],MISData[Month],$A10,MISData[Client Name],IF(Dashboard!$G$4="All","*",Dashboard!$G$4)) -> 0 | E10: Westrock Appraisal - 71A/B | F10: =SUMPRODUCT((((('Utilization Data'!$A$5:$A$364=Dashboard!$D$4)+(Dashboard!$D$4="All"))>0))*1,INDEX('Utilization Data'!$C$5:$V$364,0,MATCH($E10,'Utilization Data'!$C$4:$V$4,0))) -> 169 | H10: September | I10: =IF(Dashboard!$G$4="All",SUMPRODUCT(('Utilization Data'!$A$5:$A$364=$H10)*'Utilization Data'!$AD$5:$AD$364),SUMPRODUCT(('Utilization Data'!$A$5:$A$364=$H10)*INDEX('Utilization Data'!$C$5:$V$364,0,MATCH(Dashboard!$G$4,'Utilization Data'!$C$4:$V$4,0)))) -> 0 | K10: September | L10: =SUMPRODUCT(('Utilization Data'!$A$5:$A$364=$K10)*'Utilization Data'!$AD$5:$AD$364) -> 0 | N10: Westrock Appraisal - 71A/B | P10: =SUMPRODUCT(((('Utilization Data'!$A$5:$A$364=Dashboard!$D$4)+(Dashboard!$D$4="All"))>0)*(((('Utilization Data'!$B$5:$B$364=Dashboard!$D$14)+(Dashboard!$D$14="All"))>0)),INDEX('Utilization Data'!$C$5:$V$364,0,MATCH($E10,'Utilization Data'!$C$4:$V$4,0))) -> 0 | Q10: =IF(P10>0,SUMPRODUCT(($P$2:$P$21>0)*(ROW($P$2:$P$21)<=ROW(P10))),"") | R10: =IFERROR(AVERAGEIFS(MISData[Quality %],MISData[Month],IF(Dashboard!$D$4="All","*",Dashboard!$D$4),MISData[Client Name],$E10),"") | S10: =IF(R10="",0,R10) -> 0 | T10: =IF(R10="",0,1) -> 0
A11: October | B11: =SUMIFS(MISData[Files Received],MISData[Month],$A11,MISData[Client Name],IF(Dashboard!$G$4="All","*",Dashboard!$G$4)) -> 0 | C11: =SUMIFS(MISData[Files Delivered],MISData[Month],$A11,MISData[Client Name],IF(Dashboard!$G$4="All","*",Dashboard!$G$4)) -> 0 | E11: Westrock Appraisal - Cost Seg | F11: =SUMPRODUCT((((('Utilization Data'!$A$5:$A$364=Dashboard!$D$4)+(Dashboard!$D$4="All"))>0))*1,INDEX('Utilization Data'!$C$5:$V$364,0,MATCH($E11,'Utilization Data'!$C$4:$V$4,0))) -> 0 | H11: October | I11: =IF(Dashboard!$G$4="All",SUMPRODUCT(('Utilization Data'!$A$5:$A$364=$H11)*'Utilization Data'!$AD$5:$AD$364),SUMPRODUCT(('Utilization Data'!$A$5:$A$364=$H11)*INDEX('Utilization Data'!$C$5:$V$364,0,MATCH(Dashboard!$G$4,'Utilization Data'!$C$4:$V$4,0)))) -> 0 | K11: October | L11: =SUMPRODUCT(('Utilization Data'!$A$5:$A$364=$K11)*'Utilization Data'!$AD$5:$AD$364) -> 0 | N11: Westrock Appraisal - Cost Seg | P11: =SUMPRODUCT(((('Utilization Data'!$A$5:$A$364=Dashboard!$D$4)+(Dashboard!$D$4="All"))>0)*(((('Utilization Data'!$B$5:$B$364=Dashboard!$D$14)+(Dashboard!$D$14="All"))>0)),INDEX('Utilization Data'!$C$5:$V$364,0,MATCH($E11,'Utilization Data'!$C$4:$V$4,0))) -> 0 | Q11: =IF(P11>0,SUMPRODUCT(($P$2:$P$21>0)*(ROW($P$2:$P$21)<=ROW(P11))),"") | R11: =IFERROR(AVERAGEIFS(MISData[Quality %],MISData[Month],IF(Dashboard!$D$4="All","*",Dashboard!$D$4),MISData[Client Name],$E11),"") | S11: =IF(R11="",0,R11) -> 0 | T11: =IF(R11="",0,1) -> 0
A12: November | B12: =SUMIFS(MISData[Files Received],MISData[Month],$A12,MISData[Client Name],IF(Dashboard!$G$4="All","*",Dashboard!$G$4)) -> 0 | C12: =SUMIFS(MISData[Files Delivered],MISData[Month],$A12,MISData[Client Name],IF(Dashboard!$G$4="All","*",Dashboard!$G$4)) -> 0 | E12: DP Appraisal | F12: =SUMPRODUCT((((('Utilization Data'!$A$5:$A$364=Dashboard!$D$4)+(Dashboard!$D$4="All"))>0))*1,INDEX('Utilization Data'!$C$5:$V$364,0,MATCH($E12,'Utilization Data'!$C$4:$V$4,0))) -> 93 | H12: November | I12: =IF(Dashboard!$G$4="All",SUMPRODUCT(('Utilization Data'!$A$5:$A$364=$H12)*'Utilization Data'!$AD$5:$AD$364),SUMPRODUCT(('Utilization Data'!$A$5:$A$364=$H12)*INDEX('Utilization Data'!$C$5:$V$364,0,MATCH(Dashboard!$G$4,'Utilization Data'!$C$4:$V$4,0)))) -> 0 | K12: November | L12: =SUMPRODUCT(('Utilization Data'!$A$5:$A$364=$K12)*'Utilization Data'!$AD$5:$AD$364) -> 0 | N12: DP Appraisal | P12: =SUMPRODUCT(((('Utilization Data'!$A$5:$A$364=Dashboard!$D$4)+(Dashboard!$D$4="All"))>0)*(((('Utilization Data'!$B$5:$B$364=Dashboard!$D$14)+(Dashboard!$D$14="All"))>0)),INDEX('Utilization Data'!$C$5:$V$364,0,MATCH($E12,'Utilization Data'!$C$4:$V$4,0))) -> 48.5 | Q12: =IF(P12>0,SUMPRODUCT(($P$2:$P$21>0)*(ROW($P$2:$P$21)<=ROW(P12))),"") -> 4 | R12: =IFERROR(AVERAGEIFS(MISData[Quality %],MISData[Month],IF(Dashboard!$D$4="All","*",Dashboard!$D$4),MISData[Client Name],$E12),"") -> 1 | S12: =IF(R12="",0,R12) -> 1 | T12: =IF(R12="",0,1) -> 1
A13: December | B13: =SUMIFS(MISData[Files Received],MISData[Month],$A13,MISData[Client Name],IF(Dashboard!$G$4="All","*",Dashboard!$G$4)) -> 0 | C13: =SUMIFS(MISData[Files Delivered],MISData[Month],$A13,MISData[Client Name],IF(Dashboard!$G$4="All","*",Dashboard!$G$4)) -> 0 | E13: Real Point Appraisal | F13: =SUMPRODUCT((((('Utilization Data'!$A$5:$A$364=Dashboard!$D$4)+(Dashboard!$D$4="All"))>0))*1,INDEX('Utilization Data'!$C$5:$V$364,0,MATCH($E13,'Utilization Data'!$C$4:$V$4,0))) -> 0 | H13: December | I13: =IF(Dashboard!$G$4="All",SUMPRODUCT(('Utilization Data'!$A$5:$A$364=$H13)*'Utilization Data'!$AD$5:$AD$364),SUMPRODUCT(('Utilization Data'!$A$5:$A$364=$H13)*INDEX('Utilization Data'!$C$5:$V$364,0,MATCH(Dashboard!$G$4,'Utilization Data'!$C$4:$V$4,0)))) -> 0 | K13: December | L13: =SUMPRODUCT(('Utilization Data'!$A$5:$A$364=$K13)*'Utilization Data'!$AD$5:$AD$364) -> 0 | N13: Real Point Appraisal | P13: =SUMPRODUCT(((('Utilization Data'!$A$5:$A$364=Dashboard!$D$4)+(Dashboard!$D$4="All"))>0)*(((('Utilization Data'!$B$5:$B$364=Dashboard!$D$14)+(Dashboard!$D$14="All"))>0)),INDEX('Utilization Data'!$C$5:$V$364,0,MATCH($E13,'Utilization Data'!$C$4:$V$4,0))) -> 0 | Q13: =IF(P13>0,SUMPRODUCT(($P$2:$P$21>0)*(ROW($P$2:$P$21)<=ROW(P13))),"") | R13: =IFERROR(AVERAGEIFS(MISData[Quality %],MISData[Month],IF(Dashboard!$D$4="All","*",Dashboard!$D$4),MISData[Client Name],$E13),"") | S13: =IF(R13="",0,R13) -> 0 | T13: =IF(R13="",0,1) -> 0
E14: Pointer Appraisal | F14: =SUMPRODUCT((((('Utilization Data'!$A$5:$A$364=Dashboard!$D$4)+(Dashboard!$D$4="All"))>0))*1,INDEX('Utilization Data'!$C$5:$V$364,0,MATCH($E14,'Utilization Data'!$C$4:$V$4,0))) -> 37 | N14: Pointer Appraisal | P14: =SUMPRODUCT(((('Utilization Data'!$A$5:$A$364=Dashboard!$D$4)+(Dashboard!$D$4="All"))>0)*(((('Utilization Data'!$B$5:$B$364=Dashboard!$D$14)+(Dashboard!$D$14="All"))>0)),INDEX('Utilization Data'!$C$5:$V$364,0,MATCH($E14,'Utilization Data'!$C$4:$V$4,0))) -> 0 | Q14: =IF(P14>0,SUMPRODUCT(($P$2:$P$21>0)*(ROW($P$2:$P$21)<=ROW(P14))),"") | R14: =IFERROR(AVERAGEIFS(MISData[Quality %],MISData[Month],IF(Dashboard!$D$4="All","*",Dashboard!$D$4),MISData[Client Name],$E14),"") | S14: =IF(R14="",0,R14) -> 0 | T14: =IF(R14="",0,1) -> 0
E15: Leisure Appraisal | F15: =SUMPRODUCT((((('Utilization Data'!$A$5:$A$364=Dashboard!$D$4)+(Dashboard!$D$4="All"))>0))*1,INDEX('Utilization Data'!$C$5:$V$364,0,MATCH($E15,'Utilization Data'!$C$4:$V$4,0))) -> 14 | N15: Leisure Appraisal | P15: =SUMPRODUCT(((('Utilization Data'!$A$5:$A$364=Dashboard!$D$4)+(Dashboard!$D$4="All"))>0)*(((('Utilization Data'!$B$5:$B$364=Dashboard!$D$14)+(Dashboard!$D$14="All"))>0)),INDEX('Utilization Data'!$C$5:$V$364,0,MATCH($E15,'Utilization Data'!$C$4:$V$4,0))) -> 0 | Q15: =IF(P15>0,SUMPRODUCT(($P$2:$P$21>0)*(ROW($P$2:$P$21)<=ROW(P15))),"") | R15: =IFERROR(AVERAGEIFS(MISData[Quality %],MISData[Month],IF(Dashboard!$D$4="All","*",Dashboard!$D$4),MISData[Client Name],$E15),"") | S15: =IF(R15="",0,R15) -> 0 | T15: =IF(R15="",0,1) -> 0
E16: United Appraisal Research | F16: =SUMPRODUCT((((('Utilization Data'!$A$5:$A$364=Dashboard!$D$4)+(Dashboard!$D$4="All"))>0))*1,INDEX('Utilization Data'!$C$5:$V$364,0,MATCH($E16,'Utilization Data'!$C$4:$V$4,0))) -> 0 | N16: United Appraisal Research | P16: =SUMPRODUCT(((('Utilization Data'!$A$5:$A$364=Dashboard!$D$4)+(Dashboard!$D$4="All"))>0)*(((('Utilization Data'!$B$5:$B$364=Dashboard!$D$14)+(Dashboard!$D$14="All"))>0)),INDEX('Utilization Data'!$C$5:$V$364,0,MATCH($E16,'Utilization Data'!$C$4:$V$4,0))) -> 0 | Q16: =IF(P16>0,SUMPRODUCT(($P$2:$P$21>0)*(ROW($P$2:$P$21)<=ROW(P16))),"") | R16: =IFERROR(AVERAGEIFS(MISData[Quality %],MISData[Month],IF(Dashboard!$D$4="All","*",Dashboard!$D$4),MISData[Client Name],$E16),"") | S16: =IF(R16="",0,R16) -> 0 | T16: =IF(R16="",0,1) -> 0
E17: Breland Appraisal | F17: =SUMPRODUCT((((('Utilization Data'!$A$5:$A$364=Dashboard!$D$4)+(Dashboard!$D$4="All"))>0))*1,INDEX('Utilization Data'!$C$5:$V$364,0,MATCH($E17,'Utilization Data'!$C$4:$V$4,0))) -> 0 | N17: Breland Appraisal | P17: =SUMPRODUCT(((('Utilization Data'!$A$5:$A$364=Dashboard!$D$4)+(Dashboard!$D$4="All"))>0)*(((('Utilization Data'!$B$5:$B$364=Dashboard!$D$14)+(Dashboard!$D$14="All"))>0)),INDEX('Utilization Data'!$C$5:$V$364,0,MATCH($E17,'Utilization Data'!$C$4:$V$4,0))) -> 0 | Q17: =IF(P17>0,SUMPRODUCT(($P$2:$P$21>0)*(ROW($P$2:$P$21)<=ROW(P17))),"") | R17: =IFERROR(AVERAGEIFS(MISData[Quality %],MISData[Month],IF(Dashboard!$D$4="All","*",Dashboard!$D$4),MISData[Client Name],$E17),"") | S17: =IF(R17="",0,R17) -> 0 | T17: =IF(R17="",0,1) -> 0
E18: Proven Realty | F18: =SUMPRODUCT((((('Utilization Data'!$A$5:$A$364=Dashboard!$D$4)+(Dashboard!$D$4="All"))>0))*1,INDEX('Utilization Data'!$C$5:$V$364,0,MATCH($E18,'Utilization Data'!$C$4:$V$4,0))) -> 0 | N18: Proven Realty | P18: =SUMPRODUCT(((('Utilization Data'!$A$5:$A$364=Dashboard!$D$4)+(Dashboard!$D$4="All"))>0)*(((('Utilization Data'!$B$5:$B$364=Dashboard!$D$14)+(Dashboard!$D$14="All"))>0)),INDEX('Utilization Data'!$C$5:$V$364,0,MATCH($E18,'Utilization Data'!$C$4:$V$4,0))) -> 0 | Q18: =IF(P18>0,SUMPRODUCT(($P$2:$P$21>0)*(ROW($P$2:$P$21)<=ROW(P18))),"") | R18: =IFERROR(AVERAGEIFS(MISData[Quality %],MISData[Month],IF(Dashboard!$D$4="All","*",Dashboard!$D$4),MISData[Client Name],$E18),"") | S18: =IF(R18="",0,R18) -> 0 | T18: =IF(R18="",0,1) -> 0
E19: Voltz Commercial Realty Advisors Inc | F19: =SUMPRODUCT((((('Utilization Data'!$A$5:$A$364=Dashboard!$D$4)+(Dashboard!$D$4="All"))>0))*1,INDEX('Utilization Data'!$C$5:$V$364,0,MATCH($E19,'Utilization Data'!$C$4:$V$4,0))) -> 0 | N19: Voltz Commercial Realty Advisors Inc | P19: =SUMPRODUCT(((('Utilization Data'!$A$5:$A$364=Dashboard!$D$4)+(Dashboard!$D$4="All"))>0)*(((('Utilization Data'!$B$5:$B$364=Dashboard!$D$14)+(Dashboard!$D$14="All"))>0)),INDEX('Utilization Data'!$C$5:$V$364,0,MATCH($E19,'Utilization Data'!$C$4:$V$4,0))) -> 0 | Q19: =IF(P19>0,SUMPRODUCT(($P$2:$P$21>0)*(ROW($P$2:$P$21)<=ROW(P19))),"") | R19: =IFERROR(AVERAGEIFS(MISData[Quality %],MISData[Month],IF(Dashboard!$D$4="All","*",Dashboard!$D$4),MISData[Client Name],$E19),"") | S19: =IF(R19="",0,R19) -> 0 | T19: =IF(R19="",0,1) -> 0
E20: Mitchell Valuation | F20: =SUMPRODUCT((((('Utilization Data'!$A$5:$A$364=Dashboard!$D$4)+(Dashboard!$D$4="All"))>0))*1,INDEX('Utilization Data'!$C$5:$V$364,0,MATCH($E20,'Utilization Data'!$C$4:$V$4,0))) -> 0 | N20: Mitchell Valuation | P20: =SUMPRODUCT(((('Utilization Data'!$A$5:$A$364=Dashboard!$D$4)+(Dashboard!$D$4="All"))>0)*(((('Utilization Data'!$B$5:$B$364=Dashboard!$D$14)+(Dashboard!$D$14="All"))>0)),INDEX('Utilization Data'!$C$5:$V$364,0,MATCH($E20,'Utilization Data'!$C$4:$V$4,0))) -> 0 | Q20: =IF(P20>0,SUMPRODUCT(($P$2:$P$21>0)*(ROW($P$2:$P$21)<=ROW(P20))),"") | R20: =IFERROR(AVERAGEIFS(MISData[Quality %],MISData[Month],IF(Dashboard!$D$4="All","*",Dashboard!$D$4),MISData[Client Name],$E20),"") | S20: =IF(R20="",0,R20) -> 0 | T20: =IF(R20="",0,1) -> 0
E21: Hendry REA | F21: =SUMPRODUCT((((('Utilization Data'!$A$5:$A$364=Dashboard!$D$4)+(Dashboard!$D$4="All"))>0))*1,INDEX('Utilization Data'!$C$5:$V$364,0,MATCH($E21,'Utilization Data'!$C$4:$V$4,0))) -> 89 | N21: Hendry REA | P21: =SUMPRODUCT(((('Utilization Data'!$A$5:$A$364=Dashboard!$D$4)+(Dashboard!$D$4="All"))>0)*(((('Utilization Data'!$B$5:$B$364=Dashboard!$D$14)+(Dashboard!$D$14="All"))>0)),INDEX('Utilization Data'!$C$5:$V$364,0,MATCH($E21,'Utilization Data'!$C$4:$V$4,0))) -> 0 | Q21: =IF(P21>0,SUMPRODUCT(($P$2:$P$21>0)*(ROW($P$2:$P$21)<=ROW(P21))),"") | R21: =IFERROR(AVERAGEIFS(MISData[Quality %],MISData[Month],IF(Dashboard!$D$4="All","*",Dashboard!$D$4),MISData[Client Name],$E21),"") | S21: =IF(R21="",0,R21) -> 0 | T21: =IF(R21="",0,1) -> 0

Sheet Resource Client Utilization
A1: EMPLOYEE UTILIZATION — DETAIL VIEW
A2: Mirrors the Employee and Month selected on the Dashboard sheet — change the selection there to update this view.
A4: Selected Employee: | B4: =Dashboard!$D$14 -> Rakshitha D | D4: Selected Month: | E4: =Dashboard!$D$4 -> January
