Workbook

Sheet Dashboard
A1: Software Department – MIS Dashboard
A2: Reporting Period: August 2026 | Report Date: 05-Aug-2026
A4: Project Portfolio | D4: Resource Utilization | G4: Quality / Defects
A5: Total Projects | B5: =COUNTA('Project Status'!B5:B22) -> 3 | D5: Team Headcount | E5: =COUNTA('Resource Utilization'!B43:B100) -> 18 | G5: Total Defects Logged | H5: =COUNTA('Defect Tracking'!B5:B5) -> 1
A6: On Track | B6: =COUNTIF('Project Status'!L5:L22,"On Track") -> 2 | D6: Avg Allocation % | E6: =AVERAGE('Resource Utilization'!D43:D100) -> 1 | G6: Open | H6: =COUNTIF('Defect Tracking'!E5:E5,"Open") -> 0
A7: At Risk | B7: =COUNTIF('Project Status'!L5:L22,"At Risk") -> 0 | D7: Avg Utilization % | E7: =AVERAGE('Resource Utilization'!J43:J100) -> 0.54270833 | G7: In Progress | H7: =COUNTIF('Defect Tracking'!E5:E5,"In Progress") -> 0
A8: Delayed | B8: 1 | D8: Total Billable Hrs | E8: 148 | G8: Closed | H8: =COUNTIF('Defect Tracking'!E5:E5,"Closed") -> 1
A9: Avg % Complete | B9: =AVERAGE('Project Status'!G5:G22) -> 0.725 | D9: Total Non-Billable Hrs | E9: =SUM('Resource Utilization'!H5:H16) -> 275 | G9: Critical & Open | H9: =COUNTIFS('Defect Tracking'!D5:D5,"Critical",'Defect Tracking'!E5:E5,"<>Closed") -> 0
A10: Hours Variance % | B10: =(SUM('Project Status'!I5:I22)-SUM('Project Status'!H5:H22))/SUM('Project Status'!H5:H22) -> -0.125 | D10: Over-allocated Staff | E10: =COUNTIF('Resource Utilization'!K43:K46,"Over-allocated") -> 0 | G10: SLA Breaches | H10: =COUNTIF('Defect Tracking'!K5:K5,"Breached") -> 1
D11: Hours Variance % | E11: =(SUM('Resource Utilization'!I5:I16)-SUM('Resource Utilization'!F5:F16))/SUM('Resource Utilization'!F5:F16) -> -0.67625 | G11: SLA Compliance % | H11: =(H5-H10)/H5 -> 0
A12: Chart Source Data (auto-computed – do not edit)
A13: Project RAG Status | D13: Defect Severity (Open Items) | G13: SLA Status Breakdown
A14: On Track | B14: =COUNTIF('Project Status'!H5:H5,"On Track") -> 0 | D14: Critical | E14: =COUNTIFS('Defect Tracking'!D5:D5,"Critical",'Defect Tracking'!E5:E5,"<>Closed") -> 0 | G14: Met | H14: =COUNTIF('Defect Tracking'!K5:K5,"Met") -> 0
A15: At Risk | B15: =COUNTIF('Project Status'!H5:H5,"At Risk") -> 0 | D15: High | E15: =COUNTIFS('Defect Tracking'!D5:D5,"High",'Defect Tracking'!E5:E5,"<>Closed") -> 0 | G15: Within SLA | H15: =COUNTIF('Defect Tracking'!K5:K5,"Within SLA") -> 0
A16: Delayed | B16: =COUNTIF('Project Status'!H5:H5,"Delayed") -> 0 | D16: Medium | E16: =COUNTIFS('Defect Tracking'!D5:D5,"Medium",'Defect Tracking'!E5:E5,"<>Closed") -> 0 | G16: Breached | H16: =COUNTIF('Defect Tracking'!K5:K5,"Breached") -> 1
D17: Low | E17: =COUNTIFS('Defect Tracking'!D5:D5,"Low",'Defect Tracking'!E5:E5,"<>Closed") -> 0

Sheet Project Status
A1: Software Department – Project Status
A2: Reporting Period: August 2026 | Report Date: 05-Aug-2026
A4: S.No | B4: Project Name | C4: Project Manager | D4: Planned Activities | E4: Start Date | F4: Planned End Date | G4: % Complete | H4: Planned Hours | I4: Utilized Hours | J4: Hours Variance | K4: Variance % | L4: Status (RAG) | M4: Milestone Achieved | N4: Remarks
A5: 1 | B5: MAKO - Phase 3 | C5: Renuka | D5: IBIS World integration Plaid integration | E5: 46235 | F5: 46265 | G5: 0.75 | H5: 160 | I5: 140 | J5: =I5-H5 -> -20 | K5: =IF(H5=0,"",J5/H5) -> -0.125 | L5: On Track | M5: IBIS World Integration Plaid integration - In Progress User journey - In Progress | N5: On schedule
A6: 2 | B6: Revalix 1.0 | C6: Renuka | D6: Report Features FCV - Commercial Summary Report Cost Approach Revalix - Eval Report Revalix Data - Batch data integration, Web search - data fields | E6: 46235 | F6: 46265 | G6: 0.7 | L6: Delayed | M6: Report Features FCV - Commercial Summary Report Cost Approach Revalix - Eval Report Revalix Data - Batch data integration, Web search - data fields | N6: On schedule
A7: 3 | B7: Revalix 2.0 | C7: Renuka | D7: New UI, Data Integration,AI integration | E7: 46258 | F7: 46265 | L7: On Track | M7: Property data - In Progress | N7: On schedule
N8: On schedule

Sheet Resource Utilization
A1: Software Department – Resource Utilization
A2: Reporting Period: August 2026 | One row per employee-project assignment — the same employee can appear on multiple rows
N3: 160
A4: S.No | B4: Employee Name | C4: Role | D4: Project Allocated | E4: Allocation % | F4: Planned Hours | G4: Billable Hours | H4: Non-Billable Hours | I4: Actual Hours | J4: Hours Variance | K4: Variance % | L4: Leave/ Permission | M4: Function | N4: =E5*N3 -> 16
A5: 1 | B5: Renuka | C5: Project Manager | D5: Revalix 1.0 | E5: 0.1 | F5: =E5*N3 -> 16 | H5: 16 | I5: =G5+H5 -> 16 | J5: =F5-I5 -> 0 | K5: =IF(F5=0,"",J5/F5) -> 0
A6: 2 | B6: Renuka | C6: Project Manager | D6: Revalix 2.0 | E6: 0.3 | F6: =E6*N3 -> 48 | H6: 48 | I6: =G6+H6 -> 48 | J6: =F6-I6 -> 0 | K6: =IF(F6=0,"",J6/F6) -> 0
A7: 3 | B7: Renuka | C7: Project Manager | D7: MAKO | E7: 0.4 | F7: =E7*N3 -> 64 | H7: 64 | I7: =G7+H7 -> 64 | J7: =F7-I7 -> 0
A8: 4 | B8: Renuka | C8: Project Manager | D8: General | E8: 0.1 | F8: =E8*N3 -> 16 | H8: 16 | I8: =G8+H8 -> 16 | J8: =F8-I8 -> 0 | K8: =IF(F8=0,"",J8/F8) -> 0
A9: 4 | B9: Renuka | C9: Project Manager | D9: ValBox | E9: 0.1 | F9: =E9*N3 -> 16 | H9: 16
A10: 5 | B10: Dinesh N | C10: Software Developer | D10: Revalix 1.0 | E10: 0.7 | F10: =E10*N3 -> 112 | H10: 29 | I10: =G10+H10 -> 29 | J10: =F10-I10 -> 83 | K10: =IF(F10=0,"",J10/F10) -> 0.74107143 | L10: 8 | M10: 3
B11: Dinesh N | C11: Software Developer | D11: Revalix 2.0 | E11: 0.3 | F11: =E11*N3 -> 48
A12: 6 | B12: Vinodkumar G | C12: Software Developer | D12: Revalix 1.0 | E12: 0.7 | F12: =E12*N3 -> 112 | H12: 7 | I12: =G12+H12 -> 7 | J12: =F12-I12 -> 105 | K12: =IF(F12=0,"",J12/F12) -> 0.9375 | L12: 8 | M12: 5
A13: 7 | B13: Vinodkumar G | C13: Software Developer | D13: Revalix 2.0 | E13: 0.2 | F13: =E13*N3 -> 32 | H13: 18 | I13: =G13+H13 -> 18 | J13: =F13-I13 -> 14
A14: 8 | B14: Vinodkumar G | C14: Software Developer | D14: Training | E14: 0.1 | F14: =E14*N3 -> 16 | H14: 2 | I14: =G14+H14 -> 2 | J14: =F14-I14 -> 14
A15: 9 | B15: Aravinthan A | C15: Jr.Software Developer | D15: Revalix 1.0 | E15: 1 | F15: =E15*N3 -> 160 | H15: 30 | I15: =G15+H15 -> 30 | J15: =F15-I15 -> 130 | K15: =IF(F15=0,"",J15/F15) -> 0.8125 | M15: 8
A16: 10 | B16: Srisabarish V | C16: Jr.Software Developer | D16: Revalix 1.0 | E16: 1 | F16: =E16*N3 -> 160 | H16: 29 | I16: =G16+H16 -> 29 | J16: =F16-I16 -> 131 | K16: =IF(F16=0,"",J16/F16) -> 0.81875 | L16: 8 | M16: 3
A17: 11 | B17: Sripathi | C17: Jr.Software Developer | D17: Revalix Data | E17: 0.95 | F17: =E17*N3 -> 152 | H17: 18 | I17: =G17+H17 -> 18 | J17: =F17-I17 -> 134 | K17: =IF(F17=0,"",J17/F17) -> 0.88157895 | M17: 5
A18: 12 | B18: Sripathi | C18: Jr.Software Developer | D18: Revalix 2.0 | E18: 0.05 | F18: =E18*N3 -> 8 | H18: 16 | I18: =G18+H18 -> 16 | J18: =F18-I18 -> -8 | K18: =IF(F18=0,"",J18/F18) -> -1
A19: 13 | B19: Roshan | C19: Jr.Software Developer | D19: Revalix 2.0 | E19: 0.05 | F19: =E19*N3 -> 8 | H19: 16 | I19: =G19+H19 -> 16 | J19: =F19-I19 -> -8 | K19: =IF(F19=0,"",J19/F19) -> -1 | L19: 8 | M19: 7
A20: 14 | B20: Roshan | C20: Jr.Software Developer | D20: Finance | E20: 0.05 | F20: =E20*N3 -> 8 | H20: 9 | I20: =G20+H20 -> 9 | J20: =F20-I20 -> -1 | K20: =IF(F20=0,"",J20/F20) -> -0.125
B21: Roshan | C21: Jr.Software Developer | D21: Revalix Data | E21: 0.9 | F21: =E21*N3 -> 144
A22: 15 | B22: Joetheeswaran | C22: Jr.Software Developer | D22: Revalix Data | E22: 0.9 | F22: =E22*N3 -> 144 | H22: 28 | I22: =G22+H22 -> 28 | J22: =F22-I22 -> 116 | K22: =IF(F22=0,"",J22/F22) -> 0.80555556 | M22: 12
A23: 16 | B23: Joetheeswaran | C23: Jr.Software Developer | D23: Revalix 2.0 | E23: 0.1 | F23: =E23*N3 -> 16 | I23: =G23+H23 -> 0 | J23: =F23-I23 -> 16 | K23: =IF(F23=0,"",J23/F23) -> 1
A24: 17 | B24: Raghul | C24: Software Developer | D24: MAKO Phase 3 | E24: 1 | F24: =E24*N3 -> 160 | G24: 35 | I24: =G24+H24 -> 35 | J24: =F24-I24 -> 125 | K24: =IF(F24=0,"",J24/F24) -> 0.78125 | L24: 2 | M24: 3
A25: 18 | B25: Praveen Kumar | C25: Software Developer | D25: MAKO Phase 3 | E25: 1 | F25: =E25*N3 -> 160 | G25: 37 | I25: =G25+H25 -> 37 | J25: =F25-I25 -> 123 | K25: =IF(F25=0,"",J25/F25) -> 0.76875 | M25: 3
A26: 19 | B26: Saradha | C26: Intern | D26: Revalix 1.0 | E26: 0.1 | F26: =E26*N3 -> 16 | H26: 5 | I26: =G26+H26 -> 5 | J26: =F26-I26 -> 11 | K26: =IF(F26=0,"",J26/F26) -> 0.6875 | L26: 10 | M26: 5
A27: 20 | B27: Saradha | C27: Intern | D27: Training | E27: 0.9 | F27: =E27*N3 -> 144 | H27: 20 | I27: =G27+H27 -> 20 | J27: =F27-I27 -> 124 | K27: =IF(F27=0,"",J27/F27) -> 0.86111111
A28: 21 | B28: Kirubesh | C28: Software Developer | D28: Modum | E28: 1 | F28: =E28*N3 -> 160 | G28: 160 | I28: =G28+H28 -> 160 | J28: =F28-I28 -> 0 | K28: =IF(F28=0,"",J28/F28) -> 0
A29: 22 | B29: Deepak | C29: CRM Developer | D29: FCV | E29: 1 | F29: =E29*N3 -> 160 | G29: 160 | I29: =G29+H29 -> 160 | J29: =F29-I29 -> 0 | K29: =IF(F29=0,"",J29/F29) -> 0
A30: 23 | B30: Athish | C30: Intern | D30: Training | E30: 1 | F30: 80 | H30: 80 | I30: =G30+H30 -> 80 | J30: =F30-I30 -> 0 | K30: =IF(F30=0,"",J30/F30) -> 0
A31: 24 | B31: Joeyln | C31: Intern | D31: Training | E31: 1 | F31: 80 | H31: 80 | I31: =G31+H31 -> 80 | J31: =F31-I31 -> 0 | K31: =IF(F31=0,"",J31/F31) -> 0
A32: 25 | B32: Chandru | C32: Intern | D32: Training | E32: 1 | F32: 80 | H32: 80 | I32: =G32+H32 -> 80 | J32: =F32-I32 -> 0 | K32: =IF(F32=0,"",J32/F32) -> 0
A33: 26 | B33: Sanjay | C33: Intern | D33: Training | E33: 1 | F33: 80 | H33: 80 | I33: =G33+H33 -> 80 | J33: =F33-I33 -> 0 | K33: =IF(F33=0,"",J33/F33) -> 0
A34: 27 | B34: Ananya | C34: Intern | D34: Training | E34: 1 | F34: 80 | H34: 80 | I34: =G34+H34 -> 80 | J34: =F34-I34 -> 0 | K34: =IF(F34=0,"",J34/F34) -> 0
A41: Employee Allocation Summary (auto-computed – add a row here if you add a new employee)
A42: S.No | B42: Employee Name | C42: Role | D42: Total Allocation % | E42: Planned Hours | F42: Actual Hours | G42: Hours Variance | H42: Variance % | I42: Standard Hours | J42: Utilization % | K42: Allocation Status
A43: 1 | B43: Renuka | C43: =INDEX($C$5:$C$38,MATCH(B43,$B$5:$B$38,0)) -> Project Manager | D43: =SUMIF($B$5:$B$40,B43,$E$5:$E$40) -> 1 | E43: =SUMIF($B$5:$B$40,B43,$F$5:$F$40) -> 160 | F43: =SUMIF($B$5:$B$40,B43,$I$5:$I$40) -> 144 | G43: =F43-E43 -> -16 | H43: =IF(E43=0,"",G43/E43) -> -0.1 | I43: 160 | J43: =F43/I43 -> 0.9 | K43: =IF(D43>1,"Over-allocated",IF(D43=1,"Fully Allocated","Under-allocated")) -> Fully Allocated
A44: 2 | B44: Vinodkumar G | C44: =INDEX($C$5:$C$38,MATCH(B44,$B$5:$B$38,0)) -> Software Developer | D44: =SUMIF($B$5:$B$40,B44,$E$5:$E$40) -> 1 | E44: =SUMIF($B$5:$B$40,B44,$F$5:$F$40) -> 160 | F44: =SUMIF($B$5:$B$40,B44,$I$5:$I$40) -> 27 | G44: =F44-E44 -> -133 | H44: =IF(E44=0,"",G44/E44) -> -0.83125 | I44: 160 | J44: =F44/I44 -> 0.16875 | K44: =IF(D44>1,"Over-allocated",IF(D44=1,"Fully Allocated","Under-allocated")) -> Fully Allocated
A45: 3 | B45: Dinesh N | C45: =INDEX($C$5:$C$38,MATCH(B45,$B$5:$B$38,0)) -> Software Developer | D45: =SUMIF($B$5:$B$40,B45,$E$5:$E$40) -> 1 | E45: =SUMIF($B$5:$B$40,B45,$F$5:$F$40) -> 160 | F45: =SUMIF($B$5:$B$40,B45,$I$5:$I$40) -> 29 | G45: =F45-E45 -> -131 | H45: =IF(E45=0,"",G45/E45) -> -0.81875 | I45: 160 | J45: =F45/I45 -> 0.18125 | K45: =IF(D45>1,"Over-allocated",IF(D45=1,"Fully Allocated","Under-allocated")) -> Fully Allocated
A46: 4 | B46: Srisabarish V | C46: =INDEX($C$5:$C$38,MATCH(B46,$B$5:$B$38,0)) -> Jr.Software Developer | D46: =SUMIF($B$5:$B$40,B46,$E$5:$E$40) -> 1 | E46: =SUMIF($B$5:$B$40,B46,$F$5:$F$40) -> 160 | F46: =SUMIF($B$5:$B$40,B46,$I$5:$I$40) -> 29 | G46: =F46-E46 -> -131 | H46: =IF(E46=0,"",G46/E46) -> -0.81875 | I46: 160 | J46: =F46/I46 -> 0.18125 | K46: =IF(D46>1,"Over-allocated",IF(D46=1,"Fully Allocated","Under-allocated")) -> Fully Allocated
...

Sheet Defect Tracking
A1: Software Department – Defect / Quality Tracking
A2: Reporting Period: August 2026 | Report Date: 05-Aug-2026
A4: S.No | B4: Defect ID | C4: Project | D4: Severity | E4: Status | F4: Reported Date | G4: Resolved Date | H4: Ageing (Days) | I4: SLA Target (Days) | J4: SLA Variance (Days) | K4: SLA Status | L4: Assigned To
A5: 1 | B5: DEF-1001 | C5: Revalix | D5: Critical | E5: Closed | F5: 46244 | G5: 46247 | H5: 1 | I5: =INDEX($B$10:$B$13,MATCH(D5,$A$10:$A$13,0)) -> 0 | J5: =I5-H5 -> -1 | K5: =IF(J5<0,"Breached",IF(E5="Closed","Met","Within SLA")) -> Breached | L5: Dinesh
A8: SLA Policy (editable – target resolution days by severity)
A9: Severity | B9: Target (Days)
A10: Critical | B10: 0
A11: High | B11: 1
A12: Medium | B12: 0
A13: Low | B13: 0
